Workbook

Sheet awarie RAW
A1: a | B1: b | C1: c | D1: d | E1: e | F1: f
A2: 44613.579 | B2: Ogolne_Linia | C2: zapełnianie linii | F2: 15
A3: 44613.579 | B3: Ogolne_Linia | C3: rework motoru | F3: 10
A4: 44613.58 | B4: Awaria | C4: stacja 40 - montaż śrub | D4: problem z testem wizijnym na cover film. 11185636 | F4: 2
A5: 44613.58 | B5: Awaria | C5: stacja 50 - test szczelności | D5: przeddłużony test szczelności od 100 -147 sekund | F5: 25
A6: 44613.582 | B6: Ogolne_Linia | C6: dokładanie komponentów | D6: uzupełnienie śrub | F6: 3
A7: 44613.583 | B7: Przegląd_Serwis | C7: interwencja DUR | D7: DUR na linii,trwa naprawa | F7: 17
A8: 44613.583 | B8: Awaria | C8: stacja 50 - test szczelności | D8: przeddłużony test szczelności od 100 -147 sekund | F8: 15
A9: 44613.583 | B9: Oczekwianie | C9: brakujący komponent | D9: brak szczelnych adapterów na stacji napraw M22 do korpusów11183826 | F9: 40
A10: 44613.583 | B10: Przegląd_Serwis | C10: interwencja DUR | D10: DUR na linii,trwa naprawa | F10: 25
A11: 44613.584 | B11: Ogolne_Linia | C11: dokładanie komponentów | D11: uzupełnienie plyt, oringów | F11: 1
A12: 44613.584 | B12: Awaria | C12: stacja 50 - test szczelności | D12: przeddłużony test szczelności od 100 -160 sekund | F12: 25
A13: 44613.585 | B13: Przegląd_Serwis | C13: interwencja DUR | D13: DUR na linii,trwa naprawa | F13: 10
A14: 44613.585 | B14: Ogolne_Linia | C14: dokładanie komponentów | D14: uzupełnienie śrub | F14: 1
A15: 44613.585 | B15: Przegląd_Serwis | C15: interwencja DUR | D15: DUR na linii,trwa naprawa | F15: 45
... A21: 44613.717 | B21: Awaria | C21: stacja 60 - KUKA | D21: KUKA upuśćila kolejny motor ze st. Napraw na podłodze | F21: 15
A22: 44613.749 | B22: Ogolne_Linia | D22: przerwa od 17-40 do 18-00 | F22: 20
A23: 44613.76 | B23: Awaria | C23: stacja 60 - KUKA | D23: KUKA upuśćila kolejny motor ze st. Napraw na podłodze | F23: 15
A24: 44613.92 | B24: Przegląd_Serwis | D24: puszanie testera | F24: 5
A25: 44613.95 | B25: Przegląd_Serwis | C25: wymiana filtra | D25: wymiana filtru hg003 | F25: 20
A26: 44613.976 | B26: Awaria | C26: stacja 60 - KUKA | D26: zawieszenie robota | F26: 15
A27: 44613.994 | B27: Przegląd_Serwis | D27: przeglad dur, nie idzie SMAR st 20 | F27: 27
A28: 44614.04 | B28: Awaria | C28: stacja 60 - KUKA | D28: zawieszenie robota | F28: 15
A29: 44614.538 | B29: Ogolne_Linia | C29: dokładanie komponentów | D29: uzupelnienie śrub 7:00 | F29: 2
A30: 44614.539 | B30: Ogolne_Linia | C30: dokładanie komponentów | D30: uzupelnienie śrub 8:31 | F30: 1
A31: 44614.54 | B31: Przegląd_Serwis | C31: wymiana papieru w drukarce | D31: Wymiana etykiet i kalibracja, dostosowanie wydruku 09:00:00 | F31: 15
A32: 44614.54 | B32: Jakość | C32: selekcja komponentów | D32: selekcja+uzupelnienie plut 9:00 | F32: 5
A33: 44614.546 | B33: Ogolne_Linia | C33: dodatkowa przerwa | D33: PRZERWA 9:40-10:00 | F33: 20
A34: 44614.547 | B34: Szkolenie_Spotkanie | C34: trening operatora | D34: od 10:00-14:00 po 10 min w godzine | F34: 10
A35: 44614.549 | B35: Ogolne_Linia | C35: dokładanie komponentów | D35: w 10:32 | F35: 1
A36: 44614.549 | B36: IT_Problem | D36: problem z licenziej EXCEL 11:15 | F36: 10
A37: 44614.55 | B37: Ogolne_Linia | C37: dokładanie komponentów | D37: śruby+o-ringi | F37: 2
A38: 44614.551 | B38: Awaria | C38: stacja 60 - KUKA | D38: zawieszenie robota + szkolenie DUR 11:45 | F38: 10
A39: 44614.551 | B39: Ogolne_Linia | D39: problematyczny pomiar cardana 11184809 11:46 | F39: 3
A40: 44614.57 | B40: Szkolenie_Spotkanie | C40: spotkanie z koordynatorem | F40: 20
A41: 44614.581 | B41: Ogolne_Linia | D41: sprzątanie linii | F41: 5
A42: 44614.609 | B42: Awaria | C42: stacja 60 - KUKA | D42: Zawieszenie Kuki,naprawa przes tehnologa | F42: 23
A43: 44614.628 | B43: Awaria | C43: stacja 60 - KUKA | D43: Zawieszenie Kuki,naprawa przes tehnologa | F43: 20
A44: 44614.653 | B44: Awaria | C44: stacja 30 - montaż silnika | D44: nie dziala test wizijny,czekanie na DUR | F44: 20
A45: 44614.667 | B45: Awaria | C45: stacja 30 - montaż silnika | D45: Nie dziala test wizijny,czekanie na DUR | F45: 13
...

Sheet zejscia RAW
A1: dzien | B1: godzina | E1: cel | F1: OK | G1: NOK | H1: od celu
A2: 44613 | B2: 0600-0700 | C2: 4 | D2: (B)Nextgen, standard z zaworem | E2: 40 | F2: 36 | G2: 3 | H2: -4
A3: 44613 | B3: 0700-0800 | C3: 4 | D3: (B)Nextgen, standard z zaworem | E3: 40 | F3: 28 | G3: 1 | H3: -12
A4: 44613 | B4: 0800-0900 | C4: 4 | D4: (B)Nextgen, standard z zaworem | E4: 40 | F4: 20 | G4: 2 | H4: -20
A5: 44613 | B5: 0900-1000 | C5: 4 | D5: (B)Nextgen, standard z zaworem | E5: 40 | F5: 9 | G5: 2 | H5: -31
A6: 44613 | B6: 1000-1100 | C6: 4 | D6: (B)Nextgen, standard z zaworem | E6: 40 | F6: 20 | G6: 1 | H6: -20
A7: 44613 | B7: 1100-1200 | C7: 4 | D7: (B)Nextgen, standard z zaworem | E7: 40 | F7: 10 | G7: 0 | H7: -30
A8: 44613 | B8: 1200-1300 | C8: 4 | D8: (B)Nextgen, standard z zaworem | E8: 40 | F8: 14 | G8: 0 | H8: -26
A9: 44613 | B9: 1300-1400 | C9: 4 | D9: (B)Nextgen, standard z zaworem | E9: 40 | F9: 30 | G9: 2 | H9: -10
A10: 44613.62 | B10: 1400-1500 | C10: 4 | D10: (A)Bez zaworu | E10: 40 | F10: 28 | G10: 3 | H10: -12
A11: 44613.609 | B11: 1500-1600 | C11: 4 | D11: (A)Bez zaworu | E11: 40 | F11: 48 | G11: 2 | H11: 8
A12: 44613.625 | B12: 1600-1700 | C12: 4 | D12: (A)Bez zaworu | E12: 40 | F12: 28 | G12: 5 | H12: -12
A13: 44613.646 | B13: 1700-1800 | C13: 4 | D13: (A)Bez zaworu | E13: 40 | F13: 17 | G13: 4 | H13: -23
... A400: 44636.584 | B400: 2000-2100 | C400: 4 | D400: (A)Bez zaworu | E400: 46 | F400: 46 | G400: 1 | H400: 0
A401: 44636.584 | B401: 2100-2200 | C401: 4 | D401: (A)Bez zaworu | E401: 43 | F401: 9 | H401: -34
A402: 44636.958 | B402: 2200-2300 | C402: 4 | D402: (A)Bez zaworu | E402: 43 | F402: 10 | G402: 0 | H402: -33
A403: 44636.958 | B403: 2300-0000 | C403: 4 | D403: (A)Bez zaworu | E403: 46 | F403: 18 | G403: 2 | H403: -28
A404: 44636.958 | B404: 0000-0100 | C404: 4 | D404: (A)Bez zaworu | E404: 46 | F404: 24 | G404: 2 | H404: -22
A405: 44636.958 | B405: 0100-0200 | C405: 4 | D405: (A)Bez zaworu | E405: 32 | F405: 26 | G405: 3 | H405: -6
A406: 44636.958 | B406: 0200-0300 | C406: 4 | D406: (A)Bez zaworu | E406: 46 | F406: 38 | G406: 4 | H406: -8
A407: 44636.958 | B407: 0300-0400 | C407: 4 | D407: (A)Bez zaworu | E407: 46 | F407: 40 | G407: 3 | H407: -6
A408: 44636.958 | B408: 0400-0500 | C408: 4 | D408: (A)Bez zaworu | E408: 46 | F408: 28 | G408: 5 | H408: -18
A409: 44636.958 | B409: 0500-0600 | C409: 4 | D409: (A)Bez zaworu | E409: 43 | F409: 23 | G409: 3 | H409: -20
A410: 44637.25 | B410: 0600-0700 | C410: 3 | D410: (B)Nextgen, standard z zaworem | E410: 43 | F410: 35 | G410: 3 | H410: -8
A411: 44637.251 | B411: 0700-0800 | C411: 3 | D411: (B)Nextgen, standard z zaworem | E411: 46 | F411: 40 | G411: 2 | H411: -6
A412: 44637.251 | B412: 0800-0900 | C412: 3 | D412: (B)Nextgen, standard z zaworem | E412: 46 | F412: 40 | G412: 3 | H412: -6
A413: 44637.251 | B413: 0900-1000 | C413: 3 | D413: (B)Nextgen, standard z zaworem | E413: 32 | F413: 26 | G413: 2 | H413: -6
... A465: 44642.25 | B465: 1300-1400 | C465: 4 | D465: (A)Bez zaworu | E465: 43 | F465: 43 | G465: 1 | H465: 0
A466: 44642.621 | B466: 1400-1500 | C466: 4 | D466: (A)Bez zaworu | E466: 43 | F466: 0 | H466: -43
A467: 44642.62 | B467: 1500-1600 | C467: 4 | D467: (A)Bez zaworu | E467: 46 | F467: 0 | H467: -46
A468: 44642.62 | B468: 1600-1700 | C468: 4 | D468: (A)Bez zaworu | E468: 46 | F468: 0 | H468: -46
A469: 44642.62 | B469: 1700-1800 | C469: 4 | D469: (A)Bez zaworu | E469: 32 | F469: 0 | H469: -32
A470: 44642.62 | B470: 1800-1900 | C470: 4 | D470: (A)Bez zaworu | E470: 46 | F470: 0 | H470: -46
A471: 44642.62 | B471: 1900-2000 | C471: 4 | D471: (A)Bez zaworu | E471: 46 | F471: 0 | H471: -46
A472: 44642.62 | B472: 2000-2100 | C472: 4 | D472: (A)Bez zaworu | E472: 46 | F472: 0 | H472: -46
A473: 44642.621 | B473: 2100-2200 | C473: 4 | D473: (A)Bez zaworu | E473: 43 | F473: 0 | H473: -43
A474: 44642.621 | B474: 1400-1500 | C474: 4 | D474: (A)Bez zaworu | E474: 43 | F474: 0 | H474: -43
A475: 44642.62 | B475: 1500-1600 | C475: 4 | D475: (A)Bez zaworu | E475: 46 | F475: 0 | H475: -46
A476: 44642.62 | B476: 1600-1700 | C476: 4 | D476: (A)Bez zaworu | E476: 46 | F476: 0 | H476: -46
A477: 44642.62 | B477: 1700-1800 | C477: 4 | D477: (A)Bez zaworu | E477: 32 | F477: 0 | H477: -32
...

Sheet zejscia WORK 2
A1: Lp | B1: polaczona data z godzina | F1: cel | G1: OK | H1: NOK | I1: Wszytkie wykonane sztuki | J1: od celu | O1: Dzien_zmiana | P1: FPY | Q1: Wszystkie zmontowane / CEL | S1: Suma celu | T1: Suma OK | U1: Suma NOK | V1: Suma wszystkich zmontowanych
A2: 1 | B2: 21.02.2022 0600-0700 | C2: 0 | D2: 4 | E2: (B)Nextgen, standard z zaworem | F2: 40 | G2: 36 | H2: 3 | I2: =G2+H2 -> 39 | J2: -4 | L2: 45071 | M2: =TEXT(L2, "dd.mm.rrrr") -> 25.05.2023 | N2: 3 | O2: =_xlfn.CONCAT(M2, " ", N2) -> 25.05.2023 3 | P2: =(T2/V2)*100 -> 93.820225 | Q2: =(V2/S2)*100 -> 55.625 | S2: =SUM(OFFSET('zejscia WORK 2'!$F$2, (ROW()-2)*8, 0, 8, 1)) -> 320 | T2: =SUM(OFFSET('zejscia WORK 2'!$G$2, (ROW()-2)*8, 0, 8, 1)) -> 167 | U2: =SUM(OFFSET('zejscia WORK 2'!$H$2, (ROW()-2)*8, 0, 8, 1)) -> 11 | V2: =SUM(OFFSET('zejscia WORK 2'!$I$2, (ROW()-2)*8, 0, 8, 1)) -> 178
A3: 2 | B3: 21.02.2022 0700-0800 | C3: 0 | D3: 4 | E3: (B)Nextgen, standard z zaworem | F3: 40 | G3: 28 | H3: 1 | I3: =G3+H3 -> 29 | J3: -12 | L3: 45071 | M3: =TEXT(L3, "dd.mm.rrrr") -> 25.05.2023 | N3: 2 | O3: =_xlfn.CONCAT(M3, " ", N3) -> 25.05.2023 2 | P3: =(T3/V3)*100 -> 93.333333 | Q3: =(V3/S3)*100 -> 93.75 | S3: =SUM(OFFSET('zejscia WORK 2'!$F$2, (ROW()-2)*8, 0, 8, 1)) -> 320 | T3: =SUM(OFFSET('zejscia WORK 2'!$G$2, (ROW()-2)*8, 0, 8, 1)) -> 280 | U3: =SUM(OFFSET('zejscia WORK 2'!$H$2, (ROW()-2)*8, 0, 8, 1)) -> 20 | V3: =SUM(OFFSET('zejscia WORK 2'!$I$2, (ROW()-2)*8, 0, 8, 1)) -> 300
A4: 3 | B4: 21.02.2022 0800-0900 | C4: 0 | D4: 4 | E4: (B)Nextgen, standard z zaworem | F4: 40 | G4: 20 | H4: 2 | I4: =G4+H4 -> 22 | J4: -20 | L4: 45071 | M4: =TEXT(L4, "dd.mm.rrrr") -> 25.05.2023 | N4: 1 | O4: =_xlfn.CONCAT(M4, " ", N4) -> 25.05.2023 1 | P4: =(T4/V4)*100 -> 93.457944 | Q4: =(V4/S4)*100 -> 100.3125 | S4: =SUM(OFFSET('zejscia WORK 2'!$F$2, (ROW()-2)*8, 0, 8, 1)) -> 320 | T4: =SUM(OFFSET('zejscia WORK 2'!$G$2, (ROW()-2)*8, 0, 8, 1)) -> 300 | U4: =SUM(OFFSET('zejscia WORK 2'!$H$2, (ROW()-2)*8, 0, 8, 1)) -> 21 | V4: =SUM(OFFSET('zejscia WORK 2'!$I$2, (ROW()-2)*8, 0, 8, 1)) -> 321
A5: 4 | B5: 21.02.2022 0900-1000 | C5: 0 | D5: 4 | E5: (B)Nextgen, standard z zaworem | F5: 40 | G5: 9 | H5: 2 | I5: =G5+H5 -> 11 | J5: -31 | L5: 45070 | M5: =TEXT(L5, "dd.mm.rrrr") -> 24.05.2023 | N5: 3 | O5: =_xlfn.CONCAT(M5, " ", N5) -> 24.05.2023 3 | P5: =(T5/V5)*100 -> 92.282958 | Q5: =(V5/S5)*100 -> 97.1875 | S5: =SUM(OFFSET('zejscia WORK 2'!$F$2, (ROW()-2)*8, 0, 8, 1)) -> 320 | T5: =SUM(OFFSET('zejscia WORK 2'!$G$2, (ROW()-2)*8, 0, 8, 1)) -> 287 | U5: =SUM(OFFSET('zejscia WORK 2'!$H$2, (ROW()-2)*8, 0, 8, 1)) -> 24 | V5: =SUM(OFFSET('zejscia WORK 2'!$I$2, (ROW()-2)*8, 0, 8, 1)) -> 311
A6: 5 | B6: 21.02.2022 1000-1100 | C6: 0 | D6: 4 | E6: (B)Nextgen, standard z zaworem | F6: 40 | G6: 20 | H6: 1 | I6: =G6+H6 -> 21 | J6: -20 | L6: 45070 | M6: =TEXT(L6, "dd.mm.rrrr") -> 24.05.2023 | N6: 2 | O6: =_xlfn.CONCAT(M6, " ", N6) -> 24.05.2023 2 | P6: =(T6/V6)*100 -> 96.296296 | Q6: =(V6/S6)*100 -> 16.875 | S6: =SUM(OFFSET('zejscia WORK 2'!$F$2, (ROW()-2)*8, 0, 8, 1)) -> 320 | T6: =SUM(OFFSET('zejscia WORK 2'!$G$2, (ROW()-2)*8, 0, 8, 1)) -> 52 | U6: =SUM(OFFSET('zejscia WORK 2'!$H$2, (ROW()-2)*8, 0, 8, 1)) -> 2 | V6: =SUM(OFFSET('zejscia WORK 2'!$I$2, (ROW()-2)*8, 0, 8, 1)) -> 54
A7: 6 | B7: 21.02.2022 1100-1200 | C7: 0 | D7: 4 | E7: (B)Nextgen, standard z zaworem | F7: 40 | G7: 10 | H7: 0 | I7: =G7+H7 -> 10 | J7: -30 | L7: 45070 | M7: =TEXT(L7, "dd.mm.rrrr") -> 24.05.2023 | N7: 1 | O7: =_xlfn.CONCAT(M7, " ", N7) -> 24.05.2023 1 | P7: =(T7/V7)*100 -> 95.121951 | Q7: =(V7/S7)*100 -> 38.4375 | S7: =SUM(OFFSET('zejscia WORK 2'!$F$2, (ROW()-2)*8, 0, 8, 1)) -> 320 | T7: =SUM(OFFSET('zejscia WORK 2'!$G$2, (ROW()-2)*8, 0, 8, 1)) -> 117 | U7: =SUM(OFFSET('zejscia WORK 2'!$H$2, (ROW()-2)*8, 0, 8, 1)) -> 6 | V7: =SUM(OFFSET('zejscia WORK 2'!$I$2, (ROW()-2)*8, 0, 8, 1)) -> 123
A8: 7 | B8: 21.02.2022 1200-1300 | C8: 0 | D8: 4 | E8: (B)Nextgen, standard z zaworem | F8: 40 | G8: 14 | H8: 0 | I8: =G8+H8 -> 14 | J8: -26 | L8: 45069 | M8: =TEXT(L8, "dd.mm.rrrr") -> 23.05.2023 | N8: 3 | O8: =_xlfn.CONCAT(M8, " ", N8) -> 23.05.2023 3 | P8: =(T8/V8)*100 -> 95.121951 | Q8: =(V8/S8)*100 -> 38.4375 | S8: =SUM(OFFSET('zejscia WORK 2'!$F$2, (ROW()-2)*8, 0, 8, 1)) -> 320 | T8: =SUM(OFFSET('zejscia WORK 2'!$G$2, (ROW()-2)*8, 0, 8, 1)) -> 117 | U8: =SUM(OFFSET('zejscia WORK 2'!$H$2, (ROW()-2)*8, 0, 8, 1)) -> 6 | V8: =SUM(OFFSET('zejscia WORK 2'!$I$2, (ROW()-2)*8, 0, 8, 1)) -> 123
A9: 8 | B9: 21.02.2022 1300-1400 | C9: 0 | D9: 4 | E9: (B)Nextgen, standard z zaworem | F9: 40 | G9: 30 | H9: 2 | I9: =G9+H9 -> 32 | J9: -10 | L9: 45069 | M9: =TEXT(L9, "dd.mm.rrrr") -> 23.05.2023 | N9: 2 | O9: =_xlfn.CONCAT(M9, " ", N9) -> 23.05.2023 2 | P9: =(T9/V9)*100 -> 94.334278 | Q9: =(V9/S9)*100 -> 110.3125 | S9: =SUM(OFFSET('zejscia WORK 2'!$F$2, (ROW()-2)*8, 0, 8, 1)) -> 320 | T9: =SUM(OFFSET('zejscia WORK 2'!$G$2, (ROW()-2)*8, 0, 8, 1)) -> 333 | U9: =SUM(OFFSET('zejscia WORK 2'!$H$2, (ROW()-2)*8, 0, 8, 1)) -> 20 | V9: =SUM(OFFSET('zejscia WORK 2'!$I$2, (ROW()-2)*8, 0, 8, 1)) -> 353
A10: 9 | B10: 21.02.2022 1400-1500 | C10: 0.62 | D10: 4 | E10: (A)Bez zaworu | F10: 40 | G10: 28 | H10: 3 | I10: =G10+H10 -> 31 | J10: -12 | L10: 45069 | M10: =TEXT(L10, "dd.mm.rrrr") -> 23.05.2023 | N10: 1 | O10: =_xlfn.CONCAT(M10, " ", N10) -> 23.05.2023 1 | P10: =(T10/V10)*100 -> 93.992933 | Q10: =(V10/S10)*100 -> 88.4375 | S10: =SUM(OFFSET('zejscia WORK 2'!$F$2, (ROW()-2)*8, 0, 8, 1)) -> 320 | T10: =SUM(OFFSET('zejscia WORK 2'!$G$2, (ROW()-2)*8, 0, 8, 1)) -> 266 | U10: =SUM(OFFSET('zejscia WORK 2'!$H$2, (ROW()-2)*8, 0, 8, 1)) -> 17 | V10: =SUM(OFFSET('zejscia WORK 2'!$I$2, (ROW()-2)*8, 0, 8, 1)) -> 283
A11: 10 | B11: 21.02.2022 1500-1600 | C11: 0.60887731 | D11: 4 | E11: (A)Bez zaworu | F11: 40 | G11: 48 | H11: 2 | I11: =G11+H11 -> 50 | J11: 8 | L11: 45799 | M11: =TEXT(L11, "dd.mm.rrrr") -> 22.05.2025 | N11: 3 | O11: =_xlfn.CONCAT(M11, " ", N11) -> 22.05.2025 3 | P11: =(T11/V11)*100 -> 89.177489 | Q11: =(V11/S11)*100 -> 72.1875 | S11: =SUM(OFFSET('zejscia WORK 2'!$F$2, (ROW()-2)*8, 0, 8, 1)) -> 320 | T11: =SUM(OFFSET('zejscia WORK 2'!$G$2, (ROW()-2)*8, 0, 8, 1)) -> 206 | U11: =SUM(OFFSET('zejscia WORK 2'!$H$2, (ROW()-2)*8, 0, 8, 1)) -> 25 | V11: =SUM(OFFSET('zejscia WORK 2'!$I$2, (ROW()-2)*8, 0, 8, 1)) -> 231
A12: 11 | B12: 21.02.2022 1600-1700 | C12: 0.62501157 | D12: 4 | E12: (A)Bez zaworu | F12: 40 | G12: 28 | H12: 5 | I12: =G12+H12 -> 33 | J12: -12 | L12: 45799 | M12: =TEXT(L12, "dd.mm.rrrr") -> 22.05.2025 | N12: 2 | O12: =_xlfn.CONCAT(M12, " ", N12) -> 22.05.2025 2 | P12: =(T12/V12)*100 -> 92.971246 | Q12: =(V12/S12)*100 -> 97.8125 | S12: =SUM(OFFSET('zejscia WORK 2'!$F$2, (ROW()-2)*8, 0, 8, 1)) -> 320 | T12: =SUM(OFFSET('zejscia WORK 2'!$G$2, (ROW()-2)*8, 0, 8, 1)) -> 291 | U12: =SUM(OFFSET('zejscia WORK 2'!$H$2, (ROW()-2)*8, 0, 8, 1)) -> 22 | V12: =SUM(OFFSET('zejscia WORK 2'!$I$2, (ROW()-2)*8, 0, 8, 1)) -> 313
A13: 12 | B13: 21.02.2022 1700-1800 | C13: 0.64572917 | D13: 4 | E13: (A)Bez zaworu | F13: 40 | G13: 17 | H13: 4 | I13: =G13+H13 -> 21 | J13: -23 | L13: 45799 | M13: =TEXT(L13, "dd.mm.rrrr") -> 22.05.2025 | N13: 1 | O13: =_xlfn.CONCAT(M13, " ", N13) -> 22.05.2025 1 | P13: =(T13/V13)*100 -> 90.4 | Q13: =(V13/S13)*100 -> 39.0625 | S13: =SUM(OFFSET('zejscia WORK 2'!$F$2, (ROW()-2)*8, 0, 8, 1)) -> 320 | T13: =SUM(OFFSET('zejscia WORK 2'!$G$2, (ROW()-2)*8, 0, 8, 1)) -> 113 | U13: =SUM(OFFSET('zejscia WORK 2'!$H$2, (ROW()-2)*8, 0, 8, 1)) -> 12 | V13: =SUM(OFFSET('zejscia WORK 2'!$I$2, (ROW()-2)*8, 0, 8, 1)) -> 125
... A22: 21 | B22: 21.02.2022 0200-0300 | C22: 0.9205787 | D22: 4 | E22: (A)Bez zaworu | F22: 40 | G22: 43 | H22: 2 | I22: =G22+H22 -> 45 | J22: 3 | L22: 45796 | M22: =TEXT(L22, "dd.mm.rrrr") -> 19.05.2025 | N22: 1 | O22: =_xlfn.CONCAT(M22, " ", N22) -> 19.05.2025 1 | P22: =(T22/V22)*100 -> 96.456693 | Q22: =(V22/S22)*100 -> 79.375 | S22: =SUM(OFFSET('zejscia WORK 2'!$F$2, (ROW()-2)*8, 0, 8, 1)) -> 320 | T22: =SUM(OFFSET('zejscia WORK 2'!$G$2, (ROW()-2)*8, 0, 8, 1)) -> 245 | U22: =SUM(OFFSET('zejscia WORK 2'!$H$2, (ROW()-2)*8, 0, 8, 1)) -> 9 | V22: =SUM(OFFSET('zejscia WORK 2'!$I$2, (ROW()-2)*8, 0, 8, 1)) -> 254
A23: 22 | B23: 21.02.2022 0300-0400 | C23: 0.920625 | D23: 4 | E23: (A)Bez zaworu | F23: 40 | G23: 47 | H23: 0 | I23: =G23+H23 -> 47 | J23: 7
A24: 23 | B24: 21.02.2022 0400-0500 | C24: 0.92065972 | D24: 4 | E24: (A)Bez zaworu | F24: 40 | G24: 50 | H24: 1 | I24: =G24+H24 -> 51 | J24: 10
A25: 24 | B25: 21.02.2022 0500-0600 | C25: 0.9206713 | D25: 4 | E25: (A)Bez zaworu | F25: 40 | G25: 40 | H25: 1 | I25: =G25+H25 -> 41 | J25: 0
A26: 25 | B26: 22.02.2022 0600-0700 | C26: 0.53748843 | D26: 4 | E26: (B)Nextgen, standard z zaworem | F26: 40 | G26: 39 | H26: 7 | I26: =G26+H26 -> 46 | J26: -1
A27: 26 | B27: 22.02.2022 0700-0800 | C27: 0.53751157 | D27: 4 | E27: (B)Nextgen, standard z zaworem | F27: 40 | G27: 51 | H27: 3 | I27: =G27+H27 -> 54 | J27: 11
A28: 27 | B28: 22.02.2022 0800-0900 | C28: 0.53753472 | D28: 4 | E28: (B)Nextgen, standard z zaworem | F28: 40 | G28: 45 | H28: 2 | I28: =G28+H28 -> 47 | J28: 5
A29: 28 | B29: 22.02.2022 0900-1000 | C29: 0.53755787 | D29: 4 | E29: (B)Nextgen, standard z zaworem | F29: 40 | G29: 18 | H29: 1 | I29: =G29+H29 -> 19 | J29: -22
A30: 29 | B30: 22.02.2022 1000-1100 | C30: 0.53758102 | D30: 4 | E30: (B)Nextgen, standard z zaworem | F30: 40 | G30: 39 | H30: 3 | I30: =G30+H30 -> 42 | J30: -1
A31: 30 | B31: 22.02.2022 1100-1200 | C31: 0.53760417 | D31: 4 | E31: (B)Nextgen, standard z zaworem | F31: 40 | G31: 37 | H31: 4 | I31: =G31+H31 -> 41 | J31: -3
A32: 31 | B32: 22.02.2022 1200-1300 | C32: 0.53762731 | D32: 4 | E32: (B)Nextgen, standard z zaworem | F32: 40 | G32: 39 | H32: 2 | I32: =G32+H32 -> 41 | J32: -1
A33: 32 | B33: 22.02.2022 1300-1400 | C33: 0.53765046 | D33: 4 | E33: (B)Nextgen, standard z zaworem | F33: 40 | G33: 19 | H33: 2 | I33: =G33+H33 -> 21 | J33: -21
A34: 33 | B34: 22.02.2022 1400-1500 | C34: 0.58417824 | D34: 4 | E34: (A)Bez zaworu | F34: 40 | G34: 20 | H34: 2 | I34: =G34+H34 -> 22 | J34: -20
... A400: 399 | B400: 16.03.2022 2000-2100 | C400: 0.58403935 | D400: 4 | E400: (A)Bez zaworu | F400: 46 | G400: 46 | H400: 1 | I400: =G400+H400 -> 47 | J400: 0
A401: 400 | B401: 16.03.2022 2100-2200 | C401: 0.58407407 | D401: 4 | E401: (A)Bez zaworu | F401: 43 | G401: 9 | I401: =G401+H401 -> 9 | J401: -34
A402: 401 | B402: 16.03.2022 2200-2300 | C402: 0.95761574 | D402: 4 | E402: (A)Bez zaworu | F402: 43 | G402: 10 | H402: 0 | I402: =G402+H402 -> 10 | J402: -33
A403: 402 | B403: 16.03.2022 2300-0000 | C403: 0.95763889 | D403: 4 | E403: (A)Bez zaworu | F403: 46 | G403: 18 | H403: 2 | I403: =G403+H403 -> 20 | J403: -28
A404: 403 | B404: 16.03.2022 0000-0100 | C404: 0.95766204 | D404: 4 | E404: (A)Bez zaworu | F404: 46 | G404: 24 | H404: 2 | I404: =G404+H404 -> 26 | J404: -22
A405: 404 | B405: 16.03.2022 0100-0200 | C405: 0.95769676 | D405: 4 | E405: (A)Bez zaworu | F405: 32 | G405: 26 | H405: 3 | I405: =G405+H405 -> 29 | J405: -6
A406: 405 | B406: 16.03.2022 0200-0300 | C406: 0.95773148 | D406: 4 | E406: (A)Bez zaworu | F406: 46 | G406: 38 | H406: 4 | I406: =G406+H406 -> 42 | J406: -8
A407: 406 | B407: 16.03.2022 0300-0400 | C407: 0.95774306 | D407: 4 | E407: (A)Bez zaworu | F407: 46 | G407: 40 | H407: 3 | I407: =G407+H407 -> 43 | J407: -6
A408: 407 | B408: 16.03.2022 0400-0500 | C408: 0.95778935 | D408: 4 | E408: (A)Bez zaworu | F408: 46 | G408: 28 | H408: 5 | I408: =G408+H408 -> 33 | J408: -18
A409: 408 | B409: 16.03.2022 0500-0600 | C409: 0.95782407 | D409: 4 | E409: (A)Bez zaworu | F409: 43 | G409: 23 | H409: 3 | I409: =G409+H409 -> 26 | J409: -20
A410: 409 | B410: 17.03.2022 0600-0700 | C410: 0.25037037 | D410: 3 | E410: (B)Nextgen, standard z zaworem | F410: 43 | G410: 35 | H410: 3 | I410: =G410+H410 -> 38 | J410: -8
A411: 410 | B411: 17.03.2022 0700-0800 | C411: 0.2505787 | D411: 3 | E411: (B)Nextgen, standard z zaworem | F411: 46 | G411: 40 | H411: 2 | I411: =G411+H411 -> 42 | J411: -6
A412: 411 | B412: 17.03.2022 0800-0900 | C412: 0.25059028 | D412: 3 | E412: (B)Nextgen, standard z zaworem | F412: 46 | G412: 40 | H412: 3 | I412: =G412+H412 -> 43 | J412: -6
A413: 412 | B413: 17.03.2022 0900-1000 | C413: 0.25060185 | D413: 3 | E413: (B)Nextgen, standard z zaworem | F413: 32 | G413: 26 | H413: 2 | I413: =G413+H413 -> 28 | J413: -6
...

Sheet Awarie WORK2
F1: Klucz obcy | G1: Grupa_bledu | H1: Podgrupa_bledu | M1: Suma całego czasu straconego na przestoje w ciągu tygodnia 19-25.05.2023 | N1: Suma całego czasu straconego na przestoje DUR w ciągu tygodnia 19-25.05.2023 | O1: problemy IT | P1: Problemy Jakość | Q1: Ogólne linia | R1: szkolenia | S1: Procent awari | T1: Procent IT | U1: Procent Jakości | V1: Procent Ogólny | W1: Procent szkolenia
A2: 45072.227 | B2: 26.05.2023 | C2: 0.22708333 | D2: =IF(AND(C2>=TIME(0,0,0),C2<TIME(1,0,0)),"0000-0100", IF(AND(C2>=TIME(1,0,0),C2<TIME(2,0,0)),"0100-0200", IF(AND(C2>=TIME(2,0,0),C2<TIME(3,0,0)),"0200-0300", IF(AND(C2>=TIME(3,0,0),C2<TIME(4,0,0)),"0300-0400", IF(AND(C2>=TIME(4,0,0),C2<TIME(5,0,0)),"0400-0500", IF(AND(C2>=TIME(5,0,0),C2<TIME(6,0,0)),"0500-0600", IF(AND(C2>=TIME(6,0,0),C2<TIME(7,0,0)),"0600-0700", IF(AND(C2>=TIME(7,0,0),C2<TIME(8,0,0)),"0700-0800", IF(AND(C2>=TIME(8,0,0),C2<TIME(9,0,0)),"0800-0900", IF(AND(C2>=TIME(9,0,0),C2<TIME(10,0,0)),"0900-1000", IF(AND(C2>=TIME(10,0,0),C2<TIME(11,0,0)),"1000-1100", IF(AND(C2>=TIME(11,0,0),C2<TIME(12,0,0)),"1100-1200", IF(AND(C2>=TIME(12,0,0),C2<TIME(13,0,0)),"1200-1300", IF(AND(C2>=TIME(13,0,0),C2<TIME(14,0,0)),"1300-1400", IF(AND(C2>=TIME(14,0,0),C2<TIME(15,0,0)),"1400-1500", IF(AND(C2>=TIME(15,0,0),C2<TIME(16,0,0)),"1500-1600", IF(AND(C2>=TIME(16,0,0),C2<TIME(17,0,0)),"1600-1700", IF(AND(C2>=TIME(17,0,0),C2<TIME(18,0,0)),"1700-1800", IF(AND(C2>=TIME(18,0,0),C2<TIME(19,0,0)),"1800-1900", IF(AND(C2>=TIME(19,0,0),C2<TIME(20,0,0)),"1900-2000", IF(AND(C2>=TIME(20,0,0),C2<TIME(21,0,0)),"2000-2100", IF(AND(C2>=TIME(21,0,0),C2<TIME(22,0,0)),"2100-2200", IF(AND(C2>=TIME(22,0,0),C2<TIME(23,0,0)),"2200-2300", IF(AND(C2>=TIME(23,0,0),C2<TIME(24,0,0)),"2300-0000","Invalid Time")))))))))))))))))))))))) -> 0500-0600 | E2: 0500-0600 | F2: =_xlfn.CONCAT(B2," ",E2) -> 26.05.2023 0500-0600 | G2: Ogolne_Linia | H2: zapełnianie linii | J2: 10 | M2: =SUM(J2:J108) -> 2232 | N2: 1830 | O2: 30 | P2: 16 | Q2: 238 | R2: 118 | S2: =(N2/M2)*100 -> 81.989247 | T2: =(O2/M2)*100 -> 1.344086 | U2: =(P2/M2)*100 -> 0.71684588 | V2: =(Q2/M2)*100 -> 10.663082 | W2: =(R2/M2)*100 -> 5.2867384 | X2: =SUM(S2:W2) -> 100
A3: 45072.225 | B3: 26.05.2023 | C3: 0.225 | D3: =IF(AND(C3>=TIME(0,0,0),C3<TIME(1,0,0)),"0000-0100", IF(AND(C3>=TIME(1,0,0),C3<TIME(2,0,0)),"0100-0200", IF(AND(C3>=TIME(2,0,0),C3<TIME(3,0,0)),"0200-0300", IF(AND(C3>=TIME(3,0,0),C3<TIME(4,0,0)),"0300-0400", IF(AND(C3>=TIME(4,0,0),C3<TIME(5,0,0)),"0400-0500", IF(AND(C3>=TIME(5,0,0),C3<TIME(6,0,0)),"0500-0600", IF(AND(C3>=TIME(6,0,0),C3<TIME(7,0,0)),"0600-0700", IF(AND(C3>=TIME(7,0,0),C3<TIME(8,0,0)),"0700-0800", IF(AND(C3>=TIME(8,0,0),C3<TIME(9,0,0)),"0800-0900", IF(AND(C3>=TIME(9,0,0),C3<TIME(10,0,0)),"0900-1000", IF(AND(C3>=TIME(10,0,0),C3<TIME(11,0,0)),"1000-1100", IF(AND(C3>=TIME(11,0,0),C3<TIME(12,0,0)),"1100-1200", IF(AND(C3>=TIME(12,0,0),C3<TIME(13,0,0)),"1200-1300", IF(AND(C3>=TIME(13,0,0),C3<TIME(14,0,0)),"1300-1400", IF(AND(C3>=TIME(14,0,0),C3<TIME(15,0,0)),"1400-1500", IF(AND(C3>=TIME(15,0,0),C3<TIME(16,0,0)),"1500-1600", IF(AND(C3>=TIME(16,0,0),C3<TIME(17,0,0)),"1600-1700", IF(AND(C3>=TIME(17,0,0),C3<TIME(18,0,0)),"1700-1800", IF(AND(C3>=TIME(18,0,0),C3<TIME(19,0,0)),"1800-1900", IF(AND(C3>=TIME(19,0,0),C3<TIME(20,0,0)),"1900-2000", IF(AND(C3>=TIME(20,0,0),C3<TIME(21,0,0)),"2000-2100", IF(AND(C3>=TIME(21,0,0),C3<TIME(22,0,0)),"2100-2200", IF(AND(C3>=TIME(22,0,0),C3<TIME(23,0,0)),"2200-2300", IF(AND(C3>=TIME(23,0,0),C3<TIME(24,0,0)),"2300-0000","Invalid Time")))))))))))))))))))))))) -> 0500-0600 | E3: 0500-0600 | F3: =_xlfn.CONCAT(B3," ",E3) -> 26.05.2023 0500-0600 | G3: Przegląd_Serwis | H3: wymiana papieru w drukarce | I3: kalka | J3: 20 | M3: Suma stracenego czasu | N3: Awarie | O3: IT | P3: Jakość | Q3: Ogólne | R3: Szkolenia
A4: 45072.112 | B4: 26.05.2023 | C4: 0.11180556 | D4: =IF(AND(C4>=TIME(0,0,0),C4<TIME(1,0,0)),"0000-0100", IF(AND(C4>=TIME(1,0,0),C4<TIME(2,0,0)),"0100-0200", IF(AND(C4>=TIME(2,0,0),C4<TIME(3,0,0)),"0200-0300", IF(AND(C4>=TIME(3,0,0),C4<TIME(4,0,0)),"0300-0400", IF(AND(C4>=TIME(4,0,0),C4<TIME(5,0,0)),"0400-0500", IF(AND(C4>=TIME(5,0,0),C4<TIME(6,0,0)),"0500-0600", IF(AND(C4>=TIME(6,0,0),C4<TIME(7,0,0)),"0600-0700", IF(AND(C4>=TIME(7,0,0),C4<TIME(8,0,0)),"0700-0800", IF(AND(C4>=TIME(8,0,0),C4<TIME(9,0,0)),"0800-0900", IF(AND(C4>=TIME(9,0,0),C4<TIME(10,0,0)),"0900-1000", IF(AND(C4>=TIME(10,0,0),C4<TIME(11,0,0)),"1000-1100", IF(AND(C4>=TIME(11,0,0),C4<TIME(12,0,0)),"1100-1200", IF(AND(C4>=TIME(12,0,0),C4<TIME(13,0,0)),"1200-1300", IF(AND(C4>=TIME(13,0,0),C4<TIME(14,0,0)),"1300-1400", IF(AND(C4>=TIME(14,0,0),C4<TIME(15,0,0)),"1400-1500", IF(AND(C4>=TIME(15,0,0),C4<TIME(16,0,0)),"1500-1600", IF(AND(C4>=TIME(16,0,0),C4<TIME(17,0,0)),"1600-1700", IF(AND(C4>=TIME(17,0,0),C4<TIME(18,0,0)),"1700-1800", IF(AND(C4>=TIME(18,0,0),C4<TIME(19,0,0)),"1800-1900", IF(AND(C4>=TIME(19,0,0),C4<TIME(20,0,0)),"1900-2000", IF(AND(C4>=TIME(20,0,0),C4<TIME(21,0,0)),"2000-2100", IF(AND(C4>=TIME(21,0,0),C4<TIME(22,0,0)),"2100-2200", IF(AND(C4>=TIME(22,0,0),C4<TIME(23,0,0)),"2200-2300", IF(AND(C4>=TIME(23,0,0),C4<TIME(24,0,0)),"2300-0000","Invalid Time")))))))))))))))))))))))) -> 0200-0300 | E4: 0200-0300 | F4: =_xlfn.CONCAT(B4," ",E4) -> 26.05.2023 0200-0300 | G4: Przegląd_Serwis | H4: interwencja DUR | J4: 20 | M4: =M2/60 -> 37.2 | N4: =N2/60 -> 30.5 | O4: =O2/60 -> 0.5 | P4: =P2/60 -> 0.26666667 | Q4: =Q2/60 -> 3.9666667 | R4: =R2/60 -> 1.9666667
A5: 45072.09 | B5: 26.05.2023 | C5: 0.089583333 | D5: =IF(AND(C5>=TIME(0,0,0),C5<TIME(1,0,0)),"0000-0100", IF(AND(C5>=TIME(1,0,0),C5<TIME(2,0,0)),"0100-0200", IF(AND(C5>=TIME(2,0,0),C5<TIME(3,0,0)),"0200-0300", IF(AND(C5>=TIME(3,0,0),C5<TIME(4,0,0)),"0300-0400", IF(AND(C5>=TIME(4,0,0),C5<TIME(5,0,0)),"0400-0500", IF(AND(C5>=TIME(5,0,0),C5<TIME(6,0,0)),"0500-0600", IF(AND(C5>=TIME(6,0,0),C5<TIME(7,0,0)),"0600-0700", IF(AND(C5>=TIME(7,0,0),C5<TIME(8,0,0)),"0700-0800", IF(AND(C5>=TIME(8,0,0),C5<TIME(9,0,0)),"0800-0900", IF(AND(C5>=TIME(9,0,0),C5<TIME(10,0,0)),"0900-1000", IF(AND(C5>=TIME(10,0,0),C5<TIME(11,0,0)),"1000-1100", IF(AND(C5>=TIME(11,0,0),C5<TIME(12,0,0)),"1100-1200", IF(AND(C5>=TIME(12,0,0),C5<TIME(13,0,0)),"1200-1300", IF(AND(C5>=TIME(13,0,0),C5<TIME(14,0,0)),"1300-1400", IF(AND(C5>=TIME(14,0,0),C5<TIME(15,0,0)),"1400-1500", IF(AND(C5>=TIME(15,0,0),C5<TIME(16,0,0)),"1500-1600", IF(AND(C5>=TIME(16,0,0),C5<TIME(17,0,0)),"1600-1700", IF(AND(C5>=TIME(17,0,0),C5<TIME(18,0,0)),"1700-1800", IF(AND(C5>=TIME(18,0,0),C5<TIME(19,0,0)),"1800-1900", IF(AND(C5>=TIME(19,0,0),C5<TIME(20,0,0)),"1900-2000", IF(AND(C5>=TIME(20,0,0),C5<TIME(21,0,0)),"2000-2100", IF(AND(C5>=TIME(21,0,0),C5<TIME(22,0,0)),"2100-2200", IF(AND(C5>=TIME(22,0,0),C5<TIME(23,0,0)),"2200-2300", IF(AND(C5>=TIME(23,0,0),C5<TIME(24,0,0)),"2300-0000","Invalid Time")))))))))))))))))))))))) -> 0200-0300 | E5: 0200-0300 | F5: =_xlfn.CONCAT(B5," ",E5) -> 26.05.2023 0200-0300 | G5: Awaria | H5: stacja 50 - test szczelności | I5: Duzyj odpad motorow | J5: 40
A6: 45071.919 | B6: 25.05.2023 | C6: 0.91875 | D6: =IF(AND(C6>=TIME(0,0,0),C6<TIME(1,0,0)),"0000-0100", IF(AND(C6>=TIME(1,0,0),C6<TIME(2,0,0)),"0100-0200", IF(AND(C6>=TIME(2,0,0),C6<TIME(3,0,0)),"0200-0300", IF(AND(C6>=TIME(3,0,0),C6<TIME(4,0,0)),"0300-0400", IF(AND(C6>=TIME(4,0,0),C6<TIME(5,0,0)),"0400-0500", IF(AND(C6>=TIME(5,0,0),C6<TIME(6,0,0)),"0500-0600", IF(AND(C6>=TIME(6,0,0),C6<TIME(7,0,0)),"0600-0700", IF(AND(C6>=TIME(7,0,0),C6<TIME(8,0,0)),"0700-0800", IF(AND(C6>=TIME(8,0,0),C6<TIME(9,0,0)),"0800-0900", IF(AND(C6>=TIME(9,0,0),C6<TIME(10,0,0)),"0900-1000", IF(AND(C6>=TIME(10,0,0),C6<TIME(11,0,0)),"1000-1100", IF(AND(C6>=TIME(11,0,0),C6<TIME(12,0,0)),"1100-1200", IF(AND(C6>=TIME(12,0,0),C6<TIME(13,0,0)),"1200-1300", IF(AND(C6>=TIME(13,0,0),C6<TIME(14,0,0)),"1300-1400", IF(AND(C6>=TIME(14,0,0),C6<TIME(15,0,0)),"1400-1500", IF(AND(C6>=TIME(15,0,0),C6<TIME(16,0,0)),"1500-1600", IF(AND(C6>=TIME(16,0,0),C6<TIME(17,0,0)),"1600-1700", IF(AND(C6>=TIME(17,0,0),C6<TIME(18,0,0)),"1700-1800", IF(AND(C6>=TIME(18,0,0),C6<TIME(19,0,0)),"1800-1900", IF(AND(C6>=TIME(19,0,0),C6<TIME(20,0,0)),"1900-2000", IF(AND(C6>=TIME(20,0,0),C6<TIME(21,0,0)),"2000-2100", IF(AND(C6>=TIME(21,0,0),C6<TIME(22,0,0)),"2100-2200", IF(AND(C6>=TIME(22,0,0),C6<TIME(23,0,0)),"2200-2300", IF(AND(C6>=TIME(23,0,0),C6<TIME(24,0,0)),"2300-0000","Invalid Time")))))))))))))))))))))))) -> 2200-2300 | E6: 2200-2300 | F6: =_xlfn.CONCAT(B6," ",E6) -> 25.05.2023 2200-2300 | G6: Ogolne_Linia | H6: zapełnianie linii | I6: testy | J6: 10
A7: 45071.908 | B7: 25.05.2023 | C7: 0.90833333 | D7: =IF(AND(C7>=TIME(0,0,0),C7<TIME(1,0,0)),"0000-0100", IF(AND(C7>=TIME(1,0,0),C7<TIME(2,0,0)),"0100-0200", IF(AND(C7>=TIME(2,0,0),C7<TIME(3,0,0)),"0200-0300", IF(AND(C7>=TIME(3,0,0),C7<TIME(4,0,0)),"0300-0400", IF(AND(C7>=TIME(4,0,0),C7<TIME(5,0,0)),"0400-0500", IF(AND(C7>=TIME(5,0,0),C7<TIME(6,0,0)),"0500-0600", IF(AND(C7>=TIME(6,0,0),C7<TIME(7,0,0)),"0600-0700", IF(AND(C7>=TIME(7,0,0),C7<TIME(8,0,0)),"0700-0800", IF(AND(C7>=TIME(8,0,0),C7<TIME(9,0,0)),"0800-0900", IF(AND(C7>=TIME(9,0,0),C7<TIME(10,0,0)),"0900-1000", IF(AND(C7>=TIME(10,0,0),C7<TIME(11,0,0)),"1000-1100", IF(AND(C7>=TIME(11,0,0),C7<TIME(12,0,0)),"1100-1200", IF(AND(C7>=TIME(12,0,0),C7<TIME(13,0,0)),"1200-1300", IF(AND(C7>=TIME(13,0,0),C7<TIME(14,0,0)),"1300-1400", IF(AND(C7>=TIME(14,0,0),C7<TIME(15,0,0)),"1400-1500", IF(AND(C7>=TIME(15,0,0),C7<TIME(16,0,0)),"1500-1600", IF(AND(C7>=TIME(16,0,0),C7<TIME(17,0,0)),"1600-1700", IF(AND(C7>=TIME(17,0,0),C7<TIME(18,0,0)),"1700-1800", IF(AND(C7>=TIME(18,0,0),C7<TIME(19,0,0)),"1800-1900", IF(AND(C7>=TIME(19,0,0),C7<TIME(20,0,0)),"1900-2000", IF(AND(C7>=TIME(20,0,0),C7<TIME(21,0,0)),"2000-2100", IF(AND(C7>=TIME(21,0,0),C7<TIME(22,0,0)),"2100-2200", IF(AND(C7>=TIME(22,0,0),C7<TIME(23,0,0)),"2200-2300", IF(AND(C7>=TIME(23,0,0),C7<TIME(24,0,0)),"2300-0000","Invalid Time")))))))))))))))))))))))) -> 2100-2200 | E7: 2100-2200 | F7: =_xlfn.CONCAT(B7," ",E7) -> 25.05.2023 2100-2200 | G7: Ogolne_Linia | H7: dodatkowa przerwa | I7: dla dwóch operatorów | J7: 10
A8: 45071.833 | B8: 25.05.2023 | C8: 0.83333333 | D8: =IF(AND(C8>=TIME(0,0,0),C8<TIME(1,0,0)),"0000-0100", IF(AND(C8>=TIME(1,0,0),C8<TIME(2,0,0)),"0100-0200", IF(AND(C8>=TIME(2,0,0),C8<TIME(3,0,0)),"0200-0300", IF(AND(C8>=TIME(3,0,0),C8<TIME(4,0,0)),"0300-0400", IF(AND(C8>=TIME(4,0,0),C8<TIME(5,0,0)),"0400-0500", IF(AND(C8>=TIME(5,0,0),C8<TIME(6,0,0)),"0500-0600", IF(AND(C8>=TIME(6,0,0),C8<TIME(7,0,0)),"0600-0700", IF(AND(C8>=TIME(7,0,0),C8<TIME(8,0,0)),"0700-0800", IF(AND(C8>=TIME(8,0,0),C8<TIME(9,0,0)),"0800-0900", IF(AND(C8>=TIME(9,0,0),C8<TIME(10,0,0)),"0900-1000", IF(AND(C8>=TIME(10,0,0),C8<TIME(11,0,0)),"1000-1100", IF(AND(C8>=TIME(11,0,0),C8<TIME(12,0,0)),"1100-1200", IF(AND(C8>=TIME(12,0,0),C8<TIME(13,0,0)),"1200-1300", IF(AND(C8>=TIME(13,0,0),C8<TIME(14,0,0)),"1300-1400", IF(AND(C8>=TIME(14,0,0),C8<TIME(15,0,0)),"1400-1500", IF(AND(C8>=TIME(15,0,0),C8<TIME(16,0,0)),"1500-1600", IF(AND(C8>=TIME(16,0,0),C8<TIME(17,0,0)),"1600-1700", IF(AND(C8>=TIME(17,0,0),C8<TIME(18,0,0)),"1700-1800", IF(AND(C8>=TIME(18,0,0),C8<TIME(19,0,0)),"1800-1900", IF(AND(C8>=TIME(19,0,0),C8<TIME(20,0,0)),"1900-2000", IF(AND(C8>=TIME(20,0,0),C8<TIME(21,0,0)),"2000-2100", IF(AND(C8>=TIME(21,0,0),C8<TIME(22,0,0)),"2100-2200", IF(AND(C8>=TIME(22,0,0),C8<TIME(23,0,0)),"2200-2300", IF(AND(C8>=TIME(23,0,0),C8<TIME(24,0,0)),"2300-0000","Invalid Time")))))))))))))))))))))))) -> 2000-2100 | E8: 2000-2100 | F8: =_xlfn.CONCAT(B8," ",E8) -> 25.05.2023 2000-2100 | G8: Awaria | H8: stacja 20 - praska | I8: zabłokowany korpus.Użyto sciągacza | J8: 6 | M8: 25.05.2023 3
A9: 45071.717 | B9: 25.05.2023 | C9: 0.71666667 | D9: =IF(AND(C9>=TIME(0,0,0),C9<TIME(1,0,0)),"0000-0100", IF(AND(C9>=TIME(1,0,0),C9<TIME(2,0,0)),"0100-0200", IF(AND(C9>=TIME(2,0,0),C9<TIME(3,0,0)),"0200-0300", IF(AND(C9>=TIME(3,0,0),C9<TIME(4,0,0)),"0300-0400", IF(AND(C9>=TIME(4,0,0),C9<TIME(5,0,0)),"0400-0500", IF(AND(C9>=TIME(5,0,0),C9<TIME(6,0,0)),"0500-0600", IF(AND(C9>=TIME(6,0,0),C9<TIME(7,0,0)),"0600-0700", IF(AND(C9>=TIME(7,0,0),C9<TIME(8,0,0)),"0700-0800", IF(AND(C9>=TIME(8,0,0),C9<TIME(9,0,0)),"0800-0900", IF(AND(C9>=TIME(9,0,0),C9<TIME(10,0,0)),"0900-1000", IF(AND(C9>=TIME(10,0,0),C9<TIME(11,0,0)),"1000-1100", IF(AND(C9>=TIME(11,0,0),C9<TIME(12,0,0)),"1100-1200", IF(AND(C9>=TIME(12,0,0),C9<TIME(13,0,0)),"1200-1300", IF(AND(C9>=TIME(13,0,0),C9<TIME(14,0,0)),"1300-1400", IF(AND(C9>=TIME(14,0,0),C9<TIME(15,0,0)),"1400-1500", IF(AND(C9>=TIME(15,0,0),C9<TIME(16,0,0)),"1500-1600", IF(AND(C9>=TIME(16,0,0),C9<TIME(17,0,0)),"1600-1700", IF(AND(C9>=TIME(17,0,0),C9<TIME(18,0,0)),"1700-1800", IF(AND(C9>=TIME(18,0,0),C9<TIME(19,0,0)),"1800-1900", IF(AND(C9>=TIME(19,0,0),C9<TIME(20,0,0)),"1900-2000", IF(AND(C9>=TIME(20,0,0),C9<TIME(21,0,0)),"2000-2100", IF(AND(C9>=TIME(21,0,0),C9<TIME(22,0,0)),"2100-2200", IF(AND(C9>=TIME(22,0,0),C9<TIME(23,0,0)),"2200-2300", IF(AND(C9>=TIME(23,0,0),C9<TIME(24,0,0)),"2300-0000","Invalid Time")))))))))))))))))))))))) -> 1700-1800 | E9: 1700-1800 | F9: =_xlfn.CONCAT(B9," ",E9) -> 25.05.2023 1700-1800 | G9: Przegląd_Serwis | H9: interwencja DUR | I9: drugi adapter do regeneracji 420895 | J9: 15 | M9: 25.05.2023 2
A10: 45071.699 | B10: 25.05.2023 | C10: 0.69861111 | D10: =IF(AND(C10>=TIME(0,0,0),C10<TIME(1,0,0)),"0000-0100", IF(AND(C10>=TIME(1,0,0),C10<TIME(2,0,0)),"0100-0200", IF(AND(C10>=TIME(2,0,0),C10<TIME(3,0,0)),"0200-0300", IF(AND(C10>=TIME(3,0,0),C10<TIME(4,0,0)),"0300-0400", IF(AND(C10>=TIME(4,0,0),C10<TIME(5,0,0)),"0400-0500", IF(AND(C10>=TIME(5,0,0),C10<TIME(6,0,0)),"0500-0600", IF(AND(C10>=TIME(6,0,0),C10<TIME(7,0,0)),"0600-0700", IF(AND(C10>=TIME(7,0,0),C10<TIME(8,0,0)),"0700-0800", IF(AND(C10>=TIME(8,0,0),C10<TIME(9,0,0)),"0800-0900", IF(AND(C10>=TIME(9,0,0),C10<TIME(10,0,0)),"0900-1000", IF(AND(C10>=TIME(10,0,0),C10<TIME(11,0,0)),"1000-1100", IF(AND(C10>=TIME(11,0,0),C10<TIME(12,0,0)),"1100-1200", IF(AND(C10>=TIME(12,0,0),C10<TIME(13,0,0)),"1200-1300", IF(AND(C10>=TIME(13,0,0),C10<TIME(14,0,0)),"1300-1400", IF(AND(C10>=TIME(14,0,0),C10<TIME(15,0,0)),"1400-1500", IF(AND(C10>=TIME(15,0,0),C10<TIME(16,0,0)),"1500-1600", IF(AND(C10>=TIME(16,0,0),C10<TIME(17,0,0)),"1600-1700", IF(AND(C10>=TIME(17,0,0),C10<TIME(18,0,0)),"1700-1800", IF(AND(C10>=TIME(18,0,0),C10<TIME(19,0,0)),"1800-1900", IF(AND(C10>=TIME(19,0,0),C10<TIME(20,0,0)),"1900-2000", IF(AND(C10>=TIME(20,0,0),C10<TIME(21,0,0)),"2000-2100", IF(AND(C10>=TIME(21,0,0),C10<TIME(22,0,0)),"2100-2200", IF(AND(C10>=TIME(22,0,0),C10<TIME(23,0,0)),"2200-2300", IF(AND(C10>=TIME(23,0,0),C10<TIME(24,0,0)),"2300-0000","Invalid Time")))))))))))))))))))))))) -> 1600-1700 | E10: 1600-1700 | F10: =_xlfn.CONCAT(B10," ",E10) -> 25.05.2023 1600-1700 | G10: Awaria | H10: stacja 60 - cell 2 | I10: error Log.Zabłokowany motor w stacji.Brak możliwośći wyszarpania go ze stacji hydraulicznej.Oczekiwanie na DUR | J10: 26 | M10: 25.05.2023 1
A11: 45071.669 | B11: 25.05.2023 | C11: 0.66944444 | D11: =IF(AND(C11>=TIME(0,0,0),C11<TIME(1,0,0)),"0000-0100", IF(AND(C11>=TIME(1,0,0),C11<TIME(2,0,0)),"0100-0200", IF(AND(C11>=TIME(2,0,0),C11<TIME(3,0,0)),"0200-0300", IF(AND(C11>=TIME(3,0,0),C11<TIME(4,0,0)),"0300-0400", IF(AND(C11>=TIME(4,0,0),C11<TIME(5,0,0)),"0400-0500", IF(AND(C11>=TIME(5,0,0),C11<TIME(6,0,0)),"0500-0600", IF(AND(C11>=TIME(6,0,0),C11<TIME(7,0,0)),"0600-0700", IF(AND(C11>=TIME(7,0,0),C11<TIME(8,0,0)),"0700-0800", IF(AND(C11>=TIME(8,0,0),C11<TIME(9,0,0)),"0800-0900", IF(AND(C11>=TIME(9,0,0),C11<TIME(10,0,0)),"0900-1000", IF(AND(C11>=TIME(10,0,0),C11<TIME(11,0,0)),"1000-1100", IF(AND(C11>=TIME(11,0,0),C11<TIME(12,0,0)),"1100-1200", IF(AND(C11>=TIME(12,0,0),C11<TIME(13,0,0)),"1200-1300", IF(AND(C11>=TIME(13,0,0),C11<TIME(14,0,0)),"1300-1400", IF(AND(C11>=TIME(14,0,0),C11<TIME(15,0,0)),"1400-1500", IF(AND(C11>=TIME(15,0,0),C11<TIME(16,0,0)),"1500-1600", IF(AND(C11>=TIME(16,0,0),C11<TIME(17,0,0)),"1600-1700", IF(AND(C11>=TIME(17,0,0),C11<TIME(18,0,0)),"1700-1800", IF(AND(C11>=TIME(18,0,0),C11<TIME(19,0,0)),"1800-1900", IF(AND(C11>=TIME(19,0,0),C11<TIME(20,0,0)),"1900-2000", IF(AND(C11>=TIME(20,0,0),C11<TIME(21,0,0)),"2000-2100", IF(AND(C11>=TIME(21,0,0),C11<TIME(22,0,0)),"2100-2200", IF(AND(C11>=TIME(22,0,0),C11<TIME(23,0,0)),"2200-2300", IF(AND(C11>=TIME(23,0,0),C11<TIME(24,0,0)),"2300-0000","Invalid Time")))))))))))))))))))))))) -> 1600-1700 | E11: 1600-1700 | F11: =_xlfn.CONCAT(B11," ",E11) -> 25.05.2023 1600-1700 | G11: Awaria | H11: stacja 60 - cell 2 | I11: ułamany klucz w adapterze 429895,oddany do regeneracji | J11: 8 | M11: 24.05.2023 3
A12: 45071.656 | B12: 25.05.2023 | C12: 0.65625 | D12: =IF(AND(C12>=TIME(0,0,0),C12<TIME(1,0,0)),"0000-0100", IF(AND(C12>=TIME(1,0,0),C12<TIME(2,0,0)),"0100-0200", IF(AND(C12>=TIME(2,0,0),C12<TIME(3,0,0)),"0200-0300", IF(AND(C12>=TIME(3,0,0),C12<TIME(4,0,0)),"0300-0400", IF(AND(C12>=TIME(4,0,0),C12<TIME(5,0,0)),"0400-0500", IF(AND(C12>=TIME(5,0,0),C12<TIME(6,0,0)),"0500-0600", IF(AND(C12>=TIME(6,0,0),C12<TIME(7,0,0)),"0600-0700", IF(AND(C12>=TIME(7,0,0),C12<TIME(8,0,0)),"0700-0800", IF(AND(C12>=TIME(8,0,0),C12<TIME(9,0,0)),"0800-0900", IF(AND(C12>=TIME(9,0,0),C12<TIME(10,0,0)),"0900-1000", IF(AND(C12>=TIME(10,0,0),C12<TIME(11,0,0)),"1000-1100", IF(AND(C12>=TIME(11,0,0),C12<TIME(12,0,0)),"1100-1200", IF(AND(C12>=TIME(12,0,0),C12<TIME(13,0,0)),"1200-1300", IF(AND(C12>=TIME(13,0,0),C12<TIME(14,0,0)),"1300-1400", IF(AND(C12>=TIME(14,0,0),C12<TIME(15,0,0)),"1400-1500", IF(AND(C12>=TIME(15,0,0),C12<TIME(16,0,0)),"1500-1600", IF(AND(C12>=TIME(16,0,0),C12<TIME(17,0,0)),"1600-1700", IF(AND(C12>=TIME(17,0,0),C12<TIME(18,0,0)),"1700-1800", IF(AND(C12>=TIME(18,0,0),C12<TIME(19,0,0)),"1800-1900", IF(AND(C12>=TIME(19,0,0),C12<TIME(20,0,0)),"1900-2000", IF(AND(C12>=TIME(20,0,0),C12<TIME(21,0,0)),"2000-2100", IF(AND(C12>=TIME(21,0,0),C12<TIME(22,0,0)),"2100-2200", IF(AND(C12>=TIME(22,0,0),C12<TIME(23,0,0)),"2200-2300", IF(AND(C12>=TIME(23,0,0),C12<TIME(24,0,0)),"2300-0000","Invalid Time")))))))))))))))))))))))) -> 1500-1600 | E12: 1500-1600 | F12: =_xlfn.CONCAT(B12," ",E12) -> 25.05.2023 1500-1600 | G12: Szkolenie_Spotkanie | H12: spotkanie z koordynatorem | J12: 8 | M12: 24.05.2023 2
A13: 45071.605 | B13: 25.05.2023 | C13: 0.60486111 | D13: =IF(AND(C13>=TIME(0,0,0),C13<TIME(1,0,0)),"0000-0100", IF(AND(C13>=TIME(1,0,0),C13<TIME(2,0,0)),"0100-0200", IF(AND(C13>=TIME(2,0,0),C13<TIME(3,0,0)),"0200-0300", IF(AND(C13>=TIME(3,0,0),C13<TIME(4,0,0)),"0300-0400", IF(AND(C13>=TIME(4,0,0),C13<TIME(5,0,0)),"0400-0500", IF(AND(C13>=TIME(5,0,0),C13<TIME(6,0,0)),"0500-0600", IF(AND(C13>=TIME(6,0,0),C13<TIME(7,0,0)),"0600-0700", IF(AND(C13>=TIME(7,0,0),C13<TIME(8,0,0)),"0700-0800", IF(AND(C13>=TIME(8,0,0),C13<TIME(9,0,0)),"0800-0900", IF(AND(C13>=TIME(9,0,0),C13<TIME(10,0,0)),"0900-1000", IF(AND(C13>=TIME(10,0,0),C13<TIME(11,0,0)),"1000-1100", IF(AND(C13>=TIME(11,0,0),C13<TIME(12,0,0)),"1100-1200", IF(AND(C13>=TIME(12,0,0),C13<TIME(13,0,0)),"1200-1300", IF(AND(C13>=TIME(13,0,0),C13<TIME(14,0,0)),"1300-1400", IF(AND(C13>=TIME(14,0,0),C13<TIME(15,0,0)),"1400-1500", IF(AND(C13>=TIME(15,0,0),C13<TIME(16,0,0)),"1500-1600", IF(AND(C13>=TIME(16,0,0),C13<TIME(17,0,0)),"1600-1700", IF(AND(C13>=TIME(17,0,0),C13<TIME(18,0,0)),"1700-1800", IF(AND(C13>=TIME(18,0,0),C13<TIME(19,0,0)),"1800-1900", IF(AND(C13>=TIME(19,0,0),C13<TIME(20,0,0)),"1900-2000", IF(AND(C13>=TIME(20,0,0),C13<TIME(21,0,0)),"2000-2100", IF(AND(C13>=TIME(21,0,0),C13<TIME(22,0,0)),"2100-2200", IF(AND(C13>=TIME(22,0,0),C13<TIME(23,0,0)),"2200-2300", IF(AND(C13>=TIME(23,0,0),C13<TIME(24,0,0)),"2300-0000","Invalid Time")))))))))))))))))))))))) -> 1400-1500 | E13: 1400-1500 | F13: =_xlfn.CONCAT(B13," ",E13) -> 25.05.2023 1400-1500 | G13: Ogolne_Linia | J13: 10 | M13: 24.05.2023 1
A14: 45071.541 | B14: 25.05.2023 | C14: 0.54097222 | D14: =IF(AND(C14>=TIME(0,0,0),C14<TIME(1,0,0)),"0000-0100", IF(AND(C14>=TIME(1,0,0),C14<TIME(2,0,0)),"0100-0200", IF(AND(C14>=TIME(2,0,0),C14<TIME(3,0,0)),"0200-0300", IF(AND(C14>=TIME(3,0,0),C14<TIME(4,0,0)),"0300-0400", IF(AND(C14>=TIME(4,0,0),C14<TIME(5,0,0)),"0400-0500", IF(AND(C14>=TIME(5,0,0),C14<TIME(6,0,0)),"0500-0600", IF(AND(C14>=TIME(6,0,0),C14<TIME(7,0,0)),"0600-0700", IF(AND(C14>=TIME(7,0,0),C14<TIME(8,0,0)),"0700-0800", IF(AND(C14>=TIME(8,0,0),C14<TIME(9,0,0)),"0800-0900", IF(AND(C14>=TIME(9,0,0),C14<TIME(10,0,0)),"0900-1000", IF(AND(C14>=TIME(10,0,0),C14<TIME(11,0,0)),"1000-1100", IF(AND(C14>=TIME(11,0,0),C14<TIME(12,0,0)),"1100-1200", IF(AND(C14>=TIME(12,0,0),C14<TIME(13,0,0)),"1200-1300", IF(AND(C14>=TIME(13,0,0),C14<TIME(14,0,0)),"1300-1400", IF(AND(C14>=TIME(14,0,0),C14<TIME(15,0,0)),"1400-1500", IF(AND(C14>=TIME(15,0,0),C14<TIME(16,0,0)),"1500-1600", IF(AND(C14>=TIME(16,0,0),C14<TIME(17,0,0)),"1600-1700", IF(AND(C14>=TIME(17,0,0),C14<TIME(18,0,0)),"1700-1800", IF(AND(C14>=TIME(18,0,0),C14<TIME(19,0,0)),"1800-1900", IF(AND(C14>=TIME(19,0,0),C14<TIME(20,0,0)),"1900-2000", IF(AND(C14>=TIME(20,0,0),C14<TIME(21,0,0)),"2000-2100", IF(AND(C14>=TIME(21,0,0),C14<TIME(22,0,0)),"2100-2200", IF(AND(C14>=TIME(22,0,0),C14<TIME(23,0,0)),"2200-2300", IF(AND(C14>=TIME(23,0,0),C14<TIME(24,0,0)),"2300-0000","Invalid Time")))))))))))))))))))))))) -> 1200-1300 | E14: 1200-1300 | F14: =_xlfn.CONCAT(B14," ",E14) -> 25.05.2023 1200-1300 | G14: Awaria | H14: stacja 60 - cell 2 | I14: zablokowany motor OMPx200 w cell2, Error Log | J14: 6 | M14: 23.05.2023 3
A15: 45071.495 | B15: 25.05.2023 | C15: 0.49513889 | D15: =IF(AND(C15>=TIME(0,0,0),C15<TIME(1,0,0)),"0000-0100", IF(AND(C15>=TIME(1,0,0),C15<TIME(2,0,0)),"0100-0200", IF(AND(C15>=TIME(2,0,0),C15<TIME(3,0,0)),"0200-0300", IF(AND(C15>=TIME(3,0,0),C15<TIME(4,0,0)),"0300-0400", IF(AND(C15>=TIME(4,0,0),C15<TIME(5,0,0)),"0400-0500", IF(AND(C15>=TIME(5,0,0),C15<TIME(6,0,0)),"0500-0600", IF(AND(C15>=TIME(6,0,0),C15<TIME(7,0,0)),"0600-0700", IF(AND(C15>=TIME(7,0,0),C15<TIME(8,0,0)),"0700-0800", IF(AND(C15>=TIME(8,0,0),C15<TIME(9,0,0)),"0800-0900", IF(AND(C15>=TIME(9,0,0),C15<TIME(10,0,0)),"0900-1000", IF(AND(C15>=TIME(10,0,0),C15<TIME(11,0,0)),"1000-1100", IF(AND(C15>=TIME(11,0,0),C15<TIME(12,0,0)),"1100-1200", IF(AND(C15>=TIME(12,0,0),C15<TIME(13,0,0)),"1200-1300", IF(AND(C15>=TIME(13,0,0),C15<TIME(14,0,0)),"1300-1400", IF(AND(C15>=TIME(14,0,0),C15<TIME(15,0,0)),"1400-1500", IF(AND(C15>=TIME(15,0,0),C15<TIME(16,0,0)),"1500-1600", IF(AND(C15>=TIME(16,0,0),C15<TIME(17,0,0)),"1600-1700", IF(AND(C15>=TIME(17,0,0),C15<TIME(18,0,0)),"1700-1800", IF(AND(C15>=TIME(18,0,0),C15<TIME(19,0,0)),"1800-1900", IF(AND(C15>=TIME(19,0,0),C15<TIME(20,0,0)),"1900-2000", IF(AND(C15>=TIME(20,0,0),C15<TIME(21,0,0)),"2000-2100", IF(AND(C15>=TIME(21,0,0),C15<TIME(22,0,0)),"2100-2200", IF(AND(C15>=TIME(22,0,0),C15<TIME(23,0,0)),"2200-2300", IF(AND(C15>=TIME(23,0,0),C15<TIME(24,0,0)),"2300-0000","Invalid Time")))))))))))))))))))))))) -> 1100-1200 | E15: 1100-1200 | F15: =_xlfn.CONCAT(B15," ",E15) -> 25.05.2023 1100-1200 | G15: Awaria | H15: stacja 60 - cell 1 | I15: zablokowany motor OMPx200 w cell1, Error Log | J15: 7 | M15: 23.05.2023 2
A16: 45071.479 | B16: 25.05.2023 | C16: 0.47916667 | D16: =IF(AND(C16>=TIME(0,0,0),C16<TIME(1,0,0)),"0000-0100", IF(AND(C16>=TIME(1,0,0),C16<TIME(2,0,0)),"0100-0200", IF(AND(C16>=TIME(2,0,0),C16<TIME(3,0,0)),"0200-0300", IF(AND(C16>=TIME(3,0,0),C16<TIME(4,0,0)),"0300-0400", IF(AND(C16>=TIME(4,0,0),C16<TIME(5,0,0)),"0400-0500", IF(AND(C16>=TIME(5,0,0),C16<TIME(6,0,0)),"0500-0600", IF(AND(C16>=TIME(6,0,0),C16<TIME(7,0,0)),"0600-0700", IF(AND(C16>=TIME(7,0,0),C16<TIME(8,0,0)),"0700-0800", IF(AND(C16>=TIME(8,0,0),C16<TIME(9,0,0)),"0800-0900", IF(AND(C16>=TIME(9,0,0),C16<TIME(10,0,0)),"0900-1000", IF(AND(C16>=TIME(10,0,0),C16<TIME(11,0,0)),"1000-1100", IF(AND(C16>=TIME(11,0,0),C16<TIME(12,0,0)),"1100-1200", IF(AND(C16>=TIME(12,0,0),C16<TIME(13,0,0)),"1200-1300", IF(AND(C16>=TIME(13,0,0),C16<TIME(14,0,0)),"1300-1400", IF(AND(C16>=TIME(14,0,0),C16<TIME(15,0,0)),"1400-1500", IF(AND(C16>=TIME(15,0,0),C16<TIME(16,0,0)),"1500-1600", IF(AND(C16>=TIME(16,0,0),C16<TIME(17,0,0)),"1600-1700", IF(AND(C16>=TIME(17,0,0),C16<TIME(18,0,0)),"1700-1800", IF(AND(C16>=TIME(18,0,0),C16<TIME(19,0,0)),"1800-1900", IF(AND(C16>=TIME(19,0,0),C16<TIME(20,0,0)),"1900-2000", IF(AND(C16>=TIME(20,0,0),C16<TIME(21,0,0)),"2000-2100", IF(AND(C16>=TIME(21,0,0),C16<TIME(22,0,0)),"2100-2200", IF(AND(C16>=TIME(22,0,0),C16<TIME(23,0,0)),"2200-2300", IF(AND(C16>=TIME(23,0,0),C16<TIME(24,0,0)),"2300-0000","Invalid Time")))))))))))))))))))))))) -> 1100-1200 | E16: 1100-1200 | F16: =_xlfn.CONCAT(B16," ",E16) -> 25.05.2023 1100-1200 | G16: Awaria | H16: stacja 60 - cell 2 | I16: zablokowany motor OMPx200 w cell2, Error Log | J16: 6 | M16: 23.05.2023 1
A17: 45071.434 | B17: 25.05.2023 | C17: 0.43402778 | D17: =IF(AND(C17>=TIME(0,0,0),C17<TIME(1,0,0)),"0000-0100", IF(AND(C17>=TIME(1,0,0),C17<TIME(2,0,0)),"0100-0200", IF(AND(C17>=TIME(2,0,0),C17<TIME(3,0,0)),"0200-0300", IF(AND(C17>=TIME(3,0,0),C17<TIME(4,0,0)),"0300-0400", IF(AND(C17>=TIME(4,0,0),C17<TIME(5,0,0)),"0400-0500", IF(AND(C17>=TIME(5,0,0),C17<TIME(6,0,0)),"0500-0600", IF(AND(C17>=TIME(6,0,0),C17<TIME(7,0,0)),"0600-0700", IF(AND(C17>=TIME(7,0,0),C17<TIME(8,0,0)),"0700-0800", IF(AND(C17>=TIME(8,0,0),C17<TIME(9,0,0)),"0800-0900", IF(AND(C17>=TIME(9,0,0),C17<TIME(10,0,0)),"0900-1000", IF(AND(C17>=TIME(10,0,0),C17<TIME(11,0,0)),"1000-1100", IF(AND(C17>=TIME(11,0,0),C17<TIME(12,0,0)),"1100-1200", IF(AND(C17>=TIME(12,0,0),C17<TIME(13,0,0)),"1200-1300", IF(AND(C17>=TIME(13,0,0),C17<TIME(14,0,0)),"1300-1400", IF(AND(C17>=TIME(14,0,0),C17<TIME(15,0,0)),"1400-1500", IF(AND(C17>=TIME(15,0,0),C17<TIME(16,0,0)),"1500-1600", IF(AND(C17>=TIME(16,0,0),C17<TIME(17,0,0)),"1600-1700", IF(AND(C17>=TIME(17,0,0),C17<TIME(18,0,0)),"1700-1800", IF(AND(C17>=TIME(18,0,0),C17<TIME(19,0,0)),"1800-1900", IF(AND(C17>=TIME(19,0,0),C17<TIME(20,0,0)),"1900-2000", IF(AND(C17>=TIME(20,0,0),C17<TIME(21,0,0)),"2000-2100", IF(AND(C17>=TIME(21,0,0),C17<TIME(22,0,0)),"2100-2200", IF(AND(C17>=TIME(22,0,0),C17<TIME(23,0,0)),"2200-2300", IF(AND(C17>=TIME(23,0,0),C17<TIME(24,0,0)),"2300-0000","Invalid Time")))))))))))))))))))))))) -> 1000-1100 | E17: 1000-1100 | F17: =_xlfn.CONCAT(B17," ",E17) -> 25.05.2023 1000-1100 | G17: Awaria | H17: stacja 60 - cell 1 | I17: zablokowany motor OMPx200 w cell1, Error Log | J17: 6 | M17: 22.05.2025 3
A18: 45071.392 | B18: 25.05.2023 | C18: 0.39166667 | D18: =IF(AND(C18>=TIME(0,0,0),C18<TIME(1,0,0)),"0000-0100", IF(AND(C18>=TIME(1,0,0),C18<TIME(2,0,0)),"0100-0200", IF(AND(C18>=TIME(2,0,0),C18<TIME(3,0,0)),"0200-0300", IF(AND(C18>=TIME(3,0,0),C18<TIME(4,0,0)),"0300-0400", IF(AND(C18>=TIME(4,0,0),C18<TIME(5,0,0)),"0400-0500", IF(AND(C18>=TIME(5,0,0),C18<TIME(6,0,0)),"0500-0600", IF(AND(C18>=TIME(6,0,0),C18<TIME(7,0,0)),"0600-0700", IF(AND(C18>=TIME(7,0,0),C18<TIME(8,0,0)),"0700-0800", IF(AND(C18>=TIME(8,0,0),C18<TIME(9,0,0)),"0800-0900", IF(AND(C18>=TIME(9,0,0),C18<TIME(10,0,0)),"0900-1000", IF(AND(C18>=TIME(10,0,0),C18<TIME(11,0,0)),"1000-1100", IF(AND(C18>=TIME(11,0,0),C18<TIME(12,0,0)),"1100-1200", IF(AND(C18>=TIME(12,0,0),C18<TIME(13,0,0)),"1200-1300", IF(AND(C18>=TIME(13,0,0),C18<TIME(14,0,0)),"1300-1400", IF(AND(C18>=TIME(14,0,0),C18<TIME(15,0,0)),"1400-1500", IF(AND(C18>=TIME(15,0,0),C18<TIME(16,0,0)),"1500-1600", IF(AND(C18>=TIME(16,0,0),C18<TIME(17,0,0)),"1600-1700", IF(AND(C18>=TIME(17,0,0),C18<TIME(18,0,0)),"1700-1800", IF(AND(C18>=TIME(18,0,0),C18<TIME(19,0,0)),"1800-1900", IF(AND(C18>=TIME(19,0,0),C18<TIME(20,0,0)),"1900-2000", IF(AND(C18>=TIME(20,0,0),C18<TIME(21,0,0)),"2000-2100", IF(AND(C18>=TIME(21,0,0),C18<TIME(22,0,0)),"2100-2200", IF(AND(C18>=TIME(22,0,0),C18<TIME(23,0,0)),"2200-2300", IF(AND(C18>=TIME(23,0,0),C18<TIME(24,0,0)),"2300-0000","Invalid Time")))))))))))))))))))))))) -> 0900-1000 | E18: 0900-1000 | F18: =_xlfn.CONCAT(B18," ",E18) -> 25.05.2023 0900-1000 | G18: Szkolenie_Spotkanie | H18: spotkanie z koordynatorem | J18: 5 | M18: 22.05.2025 2
A19: 45071.375 | B19: 25.05.2023 | C19: 0.375 | D19: =IF(AND(C19>=TIME(0,0,0),C19<TIME(1,0,0)),"0000-0100", IF(AND(C19>=TIME(1,0,0),C19<TIME(2,0,0)),"0100-0200", IF(AND(C19>=TIME(2,0,0),C19<TIME(3,0,0)),"0200-0300", IF(AND(C19>=TIME(3,0,0),C19<TIME(4,0,0)),"0300-0400", IF(AND(C19>=TIME(4,0,0),C19<TIME(5,0,0)),"0400-0500", IF(AND(C19>=TIME(5,0,0),C19<TIME(6,0,0)),"0500-0600", IF(AND(C19>=TIME(6,0,0),C19<TIME(7,0,0)),"0600-0700", IF(AND(C19>=TIME(7,0,0),C19<TIME(8,0,0)),"0700-0800", IF(AND(C19>=TIME(8,0,0),C19<TIME(9,0,0)),"0800-0900", IF(AND(C19>=TIME(9,0,0),C19<TIME(10,0,0)),"0900-1000", IF(AND(C19>=TIME(10,0,0),C19<TIME(11,0,0)),"1000-1100", IF(AND(C19>=TIME(11,0,0),C19<TIME(12,0,0)),"1100-1200", IF(AND(C19>=TIME(12,0,0),C19<TIME(13,0,0)),"1200-1300", IF(AND(C19>=TIME(13,0,0),C19<TIME(14,0,0)),"1300-1400", IF(AND(C19>=TIME(14,0,0),C19<TIME(15,0,0)),"1400-1500", IF(AND(C19>=TIME(15,0,0),C19<TIME(16,0,0)),"1500-1600", IF(AND(C19>=TIME(16,0,0),C19<TIME(17,0,0)),"1600-1700", IF(AND(C19>=TIME(17,0,0),C19<TIME(18,0,0)),"1700-1800", IF(AND(C19>=TIME(18,0,0),C19<TIME(19,0,0)),"1800-1900", IF(AND(C19>=TIME(19,0,0),C19<TIME(20,0,0)),"1900-2000", IF(AND(C19>=TIME(20,0,0),C19<TIME(21,0,0)),"2000-2100", IF(AND(C19>=TIME(21,0,0),C19<TIME(22,0,0)),"2100-2200", IF(AND(C19>=TIME(22,0,0),C19<TIME(23,0,0)),"2200-2300", IF(AND(C19>=TIME(23,0,0),C19<TIME(24,0,0)),"2300-0000","Invalid Time")))))))))))))))))))))))) -> 0900-1000 | E19: 0900-1000 | F19: =_xlfn.CONCAT(B19," ",E19) -> 25.05.2023 0900-1000 | G19: Awaria | H19: stacja 60 - cell 2 | I19: zablokowany motor OMPx200 w cell2, Error Log | J19: 5 | M19: 22.05.2025 1
A20: 45071.311 | B20: 25.05.2023 | C20: 0.31111111 | D20: =IF(AND(C20>=TIME(0,0,0),C20<TIME(1,0,0)),"0000-0100", IF(AND(C20>=TIME(1,0,0),C20<TIME(2,0,0)),"0100-0200", IF(AND(C20>=TIME(2,0,0),C20<TIME(3,0,0)),"0200-0300", IF(AND(C20>=TIME(3,0,0),C20<TIME(4,0,0)),"0300-0400", IF(AND(C20>=TIME(4,0,0),C20<TIME(5,0,0)),"0400-0500", IF(AND(C20>=TIME(5,0,0),C20<TIME(6,0,0)),"0500-0600", IF(AND(C20>=TIME(6,0,0),C20<TIME(7,0,0)),"0600-0700", IF(AND(C20>=TIME(7,0,0),C20<TIME(8,0,0)),"0700-0800", IF(AND(C20>=TIME(8,0,0),C20<TIME(9,0,0)),"0800-0900", IF(AND(C20>=TIME(9,0,0),C20<TIME(10,0,0)),"0900-1000", IF(AND(C20>=TIME(10,0,0),C20<TIME(11,0,0)),"1000-1100", IF(AND(C20>=TIME(11,0,0),C20<TIME(12,0,0)),"1100-1200", IF(AND(C20>=TIME(12,0,0),C20<TIME(13,0,0)),"1200-1300", IF(AND(C20>=TIME(13,0,0),C20<TIME(14,0,0)),"1300-1400", IF(AND(C20>=TIME(14,0,0),C20<TIME(15,0,0)),"1400-1500", IF(AND(C20>=TIME(15,0,0),C20<TIME(16,0,0)),"1500-1600", IF(AND(C20>=TIME(16,0,0),C20<TIME(17,0,0)),"1600-1700", IF(AND(C20>=TIME(17,0,0),C20<TIME(18,0,0)),"1700-1800", IF(AND(C20>=TIME(18,0,0),C20<TIME(19,0,0)),"1800-1900", IF(AND(C20>=TIME(19,0,0),C20<TIME(20,0,0)),"1900-2000", IF(AND(C20>=TIME(20,0,0),C20<TIME(21,0,0)),"2000-2100", IF(AND(C20>=TIME(21,0,0),C20<TIME(22,0,0)),"2100-2200", IF(AND(C20>=TIME(22,0,0),C20<TIME(23,0,0)),"2200-2300", IF(AND(C20>=TIME(23,0,0),C20<TIME(24,0,0)),"2300-0000","Invalid Time")))))))))))))))))))))))) -> 0700-0800 | E20: 0700-0800 | F20: =_xlfn.CONCAT(B20," ",E20) -> 25.05.2023 0700-0800 | G20: Przegląd_Serwis | H20: interwencja DUR | I20: st.50 | J20: 22 | M20: 21.05.2025 3
A21: 45071.31 | B21: 25.05.2023 | C21: 0.30972222 | D21: =IF(AND(C21>=TIME(0,0,0),C21<TIME(1,0,0)),"0000-0100", IF(AND(C21>=TIME(1,0,0),C21<TIME(2,0,0)),"0100-0200", IF(AND(C21>=TIME(2,0,0),C21<TIME(3,0,0)),"0200-0300", IF(AND(C21>=TIME(3,0,0),C21<TIME(4,0,0)),"0300-0400", IF(AND(C21>=TIME(4,0,0),C21<TIME(5,0,0)),"0400-0500", IF(AND(C21>=TIME(5,0,0),C21<TIME(6,0,0)),"0500-0600", IF(AND(C21>=TIME(6,0,0),C21<TIME(7,0,0)),"0600-0700", IF(AND(C21>=TIME(7,0,0),C21<TIME(8,0,0)),"0700-0800", IF(AND(C21>=TIME(8,0,0),C21<TIME(9,0,0)),"0800-0900", IF(AND(C21>=TIME(9,0,0),C21<TIME(10,0,0)),"0900-1000", IF(AND(C21>=TIME(10,0,0),C21<TIME(11,0,0)),"1000-1100", IF(AND(C21>=TIME(11,0,0),C21<TIME(12,0,0)),"1100-1200", IF(AND(C21>=TIME(12,0,0),C21<TIME(13,0,0)),"1200-1300", IF(AND(C21>=TIME(13,0,0),C21<TIME(14,0,0)),"1300-1400", IF(AND(C21>=TIME(14,0,0),C21<TIME(15,0,0)),"1400-1500", IF(AND(C21>=TIME(15,0,0),C21<TIME(16,0,0)),"1500-1600", IF(AND(C21>=TIME(16,0,0),C21<TIME(17,0,0)),"1600-1700", IF(AND(C21>=TIME(17,0,0),C21<TIME(18,0,0)),"1700-1800", IF(AND(C21>=TIME(18,0,0),C21<TIME(19,0,0)),"1800-1900", IF(AND(C21>=TIME(19,0,0),C21<TIME(20,0,0)),"1900-2000", IF(AND(C21>=TIME(20,0,0),C21<TIME(21,0,0)),"2000-2100", IF(AND(C21>=TIME(21,0,0),C21<TIME(22,0,0)),"2100-2200", IF(AND(C21>=TIME(22,0,0),C21<TIME(23,0,0)),"2200-2300", IF(AND(C21>=TIME(23,0,0),C21<TIME(24,0,0)),"2300-0000","Invalid Time")))))))))))))))))))))))) -> 0700-0800 | E21: 0700-0800 | F21: =_xlfn.CONCAT(B21," ",E21) -> 25.05.2023 0700-0800 | G21: Awaria | H21: stacja 50 - test szczelności | I21: uszkodżony korpus z doły po testy, gniazdo komory B do szlifowania | J21: 2 | M21: 21.05.2025 2
A22: 45071.247 | B22: 25.05.2023 | C22: 0.24722222 | D22: =IF(AND(C22>=TIME(0,0,0),C22<TIME(1,0,0)),"0000-0100", IF(AND(C22>=TIME(1,0,0),C22<TIME(2,0,0)),"0100-0200", IF(AND(C22>=TIME(2,0,0),C22<TIME(3,0,0)),"0200-0300", IF(AND(C22>=TIME(3,0,0),C22<TIME(4,0,0)),"0300-0400", IF(AND(C22>=TIME(4,0,0),C22<TIME(5,0,0)),"0400-0500", IF(AND(C22>=TIME(5,0,0),C22<TIME(6,0,0)),"0500-0600", IF(AND(C22>=TIME(6,0,0),C22<TIME(7,0,0)),"0600-0700", IF(AND(C22>=TIME(7,0,0),C22<TIME(8,0,0)),"0700-0800", IF(AND(C22>=TIME(8,0,0),C22<TIME(9,0,0)),"0800-0900", IF(AND(C22>=TIME(9,0,0),C22<TIME(10,0,0)),"0900-1000", IF(AND(C22>=TIME(10,0,0),C22<TIME(11,0,0)),"1000-1100", IF(AND(C22>=TIME(11,0,0),C22<TIME(12,0,0)),"1100-1200", IF(AND(C22>=TIME(12,0,0),C22<TIME(13,0,0)),"1200-1300", IF(AND(C22>=TIME(13,0,0),C22<TIME(14,0,0)),"1300-1400", IF(AND(C22>=TIME(14,0,0),C22<TIME(15,0,0)),"1400-1500", IF(AND(C22>=TIME(15,0,0),C22<TIME(16,0,0)),"1500-1600", IF(AND(C22>=TIME(16,0,0),C22<TIME(17,0,0)),"1600-1700", IF(AND(C22>=TIME(17,0,0),C22<TIME(18,0,0)),"1700-1800", IF(AND(C22>=TIME(18,0,0),C22<TIME(19,0,0)),"1800-1900", IF(AND(C22>=TIME(19,0,0),C22<TIME(20,0,0)),"1900-2000", IF(AND(C22>=TIME(20,0,0),C22<TIME(21,0,0)),"2000-2100", IF(AND(C22>=TIME(21,0,0),C22<TIME(22,0,0)),"2100-2200", IF(AND(C22>=TIME(22,0,0),C22<TIME(23,0,0)),"2200-2300", IF(AND(C22>=TIME(23,0,0),C22<TIME(24,0,0)),"2300-0000","Invalid Time")))))))))))))))))))))))) -> 0500-0600 | E22: 0500-0600 | F22: =_xlfn.CONCAT(B22," ",E22) -> 25.05.2023 0500-0600 | G22: Ogolne_Linia | I22: testy kontolne | J22: 10 | M22: 21.05.2025 1
A23: 45071.172 | B23: 25.05.2023 | C23: 0.17152778 | D23: =IF(AND(C23>=TIME(0,0,0),C23<TIME(1,0,0)),"0000-0100", IF(AND(C23>=TIME(1,0,0),C23<TIME(2,0,0)),"0100-0200", IF(AND(C23>=TIME(2,0,0),C23<TIME(3,0,0)),"0200-0300", IF(AND(C23>=TIME(3,0,0),C23<TIME(4,0,0)),"0300-0400", IF(AND(C23>=TIME(4,0,0),C23<TIME(5,0,0)),"0400-0500", IF(AND(C23>=TIME(5,0,0),C23<TIME(6,0,0)),"0500-0600", IF(AND(C23>=TIME(6,0,0),C23<TIME(7,0,0)),"0600-0700", IF(AND(C23>=TIME(7,0,0),C23<TIME(8,0,0)),"0700-0800", IF(AND(C23>=TIME(8,0,0),C23<TIME(9,0,0)),"0800-0900", IF(AND(C23>=TIME(9,0,0),C23<TIME(10,0,0)),"0900-1000", IF(AND(C23>=TIME(10,0,0),C23<TIME(11,0,0)),"1000-1100", IF(AND(C23>=TIME(11,0,0),C23<TIME(12,0,0)),"1100-1200", IF(AND(C23>=TIME(12,0,0),C23<TIME(13,0,0)),"1200-1300", IF(AND(C23>=TIME(13,0,0),C23<TIME(14,0,0)),"1300-1400", IF(AND(C23>=TIME(14,0,0),C23<TIME(15,0,0)),"1400-1500", IF(AND(C23>=TIME(15,0,0),C23<TIME(16,0,0)),"1500-1600", IF(AND(C23>=TIME(16,0,0),C23<TIME(17,0,0)),"1600-1700", IF(AND(C23>=TIME(17,0,0),C23<TIME(18,0,0)),"1700-1800", IF(AND(C23>=TIME(18,0,0),C23<TIME(19,0,0)),"1800-1900", IF(AND(C23>=TIME(19,0,0),C23<TIME(20,0,0)),"1900-2000", IF(AND(C23>=TIME(20,0,0),C23<TIME(21,0,0)),"2000-2100", IF(AND(C23>=TIME(21,0,0),C23<TIME(22,0,0)),"2100-2200", IF(AND(C23>=TIME(22,0,0),C23<TIME(23,0,0)),"2200-2300", IF(AND(C23>=TIME(23,0,0),C23<TIME(24,0,0)),"2300-0000","Invalid Time")))))))))))))))))))))))) -> 0400-0500 | E23: 0400-0500 | F23: =_xlfn.CONCAT(B23," ",E23) -> 25.05.2023 0400-0500 | G23: Awaria | H23: stacja 60 - KUKA | I23: zawiszenie | J23: 5 | M23: 20.05.2025 3
A24: 45071.149 | B24: 25.05.2023 | C24: 0.14861111 | D24: =IF(AND(C24>=TIME(0,0,0),C24<TIME(1,0,0)),"0000-0100", IF(AND(C24>=TIME(1,0,0),C24<TIME(2,0,0)),"0100-0200", IF(AND(C24>=TIME(2,0,0),C24<TIME(3,0,0)),"0200-0300", IF(AND(C24>=TIME(3,0,0),C24<TIME(4,0,0)),"0300-0400", IF(AND(C24>=TIME(4,0,0),C24<TIME(5,0,0)),"0400-0500", IF(AND(C24>=TIME(5,0,0),C24<TIME(6,0,0)),"0500-0600", IF(AND(C24>=TIME(6,0,0),C24<TIME(7,0,0)),"0600-0700", IF(AND(C24>=TIME(7,0,0),C24<TIME(8,0,0)),"0700-0800", IF(AND(C24>=TIME(8,0,0),C24<TIME(9,0,0)),"0800-0900", IF(AND(C24>=TIME(9,0,0),C24<TIME(10,0,0)),"0900-1000", IF(AND(C24>=TIME(10,0,0),C24<TIME(11,0,0)),"1000-1100", IF(AND(C24>=TIME(11,0,0),C24<TIME(12,0,0)),"1100-1200", IF(AND(C24>=TIME(12,0,0),C24<TIME(13,0,0)),"1200-1300", IF(AND(C24>=TIME(13,0,0),C24<TIME(14,0,0)),"1300-1400", IF(AND(C24>=TIME(14,0,0),C24<TIME(15,0,0)),"1400-1500", IF(AND(C24>=TIME(15,0,0),C24<TIME(16,0,0)),"1500-1600", IF(AND(C24>=TIME(16,0,0),C24<TIME(17,0,0)),"1600-1700", IF(AND(C24>=TIME(17,0,0),C24<TIME(18,0,0)),"1700-1800", IF(AND(C24>=TIME(18,0,0),C24<TIME(19,0,0)),"1800-1900", IF(AND(C24>=TIME(19,0,0),C24<TIME(20,0,0)),"1900-2000", IF(AND(C24>=TIME(20,0,0),C24<TIME(21,0,0)),"2000-2100", IF(AND(C24>=TIME(21,0,0),C24<TIME(22,0,0)),"2100-2200", IF(AND(C24>=TIME(22,0,0),C24<TIME(23,0,0)),"2200-2300", IF(AND(C24>=TIME(23,0,0),C24<TIME(24,0,0)),"2300-0000","Invalid Time")))))))))))))))))))))))) -> 0300-0400 | E24: 0300-0400 | F24: =_xlfn.CONCAT(B24," ",E24) -> 25.05.2023 0300-0400 | G24: Awaria | H24: stacja 60 - cell 2 | I24: dolewanie oleju w zbiornik 0310 | J24: 24 | M24: 20.05.2025 2
A25: 45071.148 | B25: 25.05.2023 | C25: 0.14791667 | D25: =IF(AND(C25>=TIME(0,0,0),C25<TIME(1,0,0)),"0000-0100", IF(AND(C25>=TIME(1,0,0),C25<TIME(2,0,0)),"0100-0200", IF(AND(C25>=TIME(2,0,0),C25<TIME(3,0,0)),"0200-0300", IF(AND(C25>=TIME(3,0,0),C25<TIME(4,0,0)),"0300-0400", IF(AND(C25>=TIME(4,0,0),C25<TIME(5,0,0)),"0400-0500", IF(AND(C25>=TIME(5,0,0),C25<TIME(6,0,0)),"0500-0600", IF(AND(C25>=TIME(6,0,0),C25<TIME(7,0,0)),"0600-0700", IF(AND(C25>=TIME(7,0,0),C25<TIME(8,0,0)),"0700-0800", IF(AND(C25>=TIME(8,0,0),C25<TIME(9,0,0)),"0800-0900", IF(AND(C25>=TIME(9,0,0),C25<TIME(10,0,0)),"0900-1000", IF(AND(C25>=TIME(10,0,0),C25<TIME(11,0,0)),"1000-1100", IF(AND(C25>=TIME(11,0,0),C25<TIME(12,0,0)),"1100-1200", IF(AND(C25>=TIME(12,0,0),C25<TIME(13,0,0)),"1200-1300", IF(AND(C25>=TIME(13,0,0),C25<TIME(14,0,0)),"1300-1400", IF(AND(C25>=TIME(14,0,0),C25<TIME(15,0,0)),"1400-1500", IF(AND(C25>=TIME(15,0,0),C25<TIME(16,0,0)),"1500-1600", IF(AND(C25>=TIME(16,0,0),C25<TIME(17,0,0)),"1600-1700", IF(AND(C25>=TIME(17,0,0),C25<TIME(18,0,0)),"1700-1800", IF(AND(C25>=TIME(18,0,0),C25<TIME(19,0,0)),"1800-1900", IF(AND(C25>=TIME(19,0,0),C25<TIME(20,0,0)),"1900-2000", IF(AND(C25>=TIME(20,0,0),C25<TIME(21,0,0)),"2000-2100", IF(AND(C25>=TIME(21,0,0),C25<TIME(22,0,0)),"2100-2200", IF(AND(C25>=TIME(22,0,0),C25<TIME(23,0,0)),"2200-2300", IF(AND(C25>=TIME(23,0,0),C25<TIME(24,0,0)),"2300-0000","Invalid Time")))))))))))))))))))))))) -> 0300-0400 | E25: 0300-0400 | F25: =_xlfn.CONCAT(B25," ",E25) -> 25.05.2023 0300-0400 | G25: Awaria | H25: stacja 50 - test szczelności | I25: czyszczenie komory | J25: 20 | M25: 20.05.2025 1
