Workbook

Sheet zejscia WORK 2
A1: Lp | B1: Połączone data z godziną | F1: cel | G1: OK | H1: NOK | I1: Wszystkie | J1: od celu | O1: Dzien_zmiana | P1: FPY | Q1: Wszystkie zmontowane / CEL | S1: Suma celu | T1: Suma OK | U1: Suma NOK | V1: Suma wszystkich zmontowanych
A2: 1 | B2: 42421 | C2: 0 | D2: 4 | E2: (B)Nextgen, standard z zaworem | F2: =40*0.75 -> 30 | G2: 27 | H2: 2 | I2: 29 | J2: 3 | M2: 21.02.2016 -1 | N2: 1 | P2: =(T2/V2)*100 -> 92.70073 | Q2: =(V2/S2)*100 -> 57.083333 | S2: =SUM(OFFSET('zejscia WORK 2'!$F$2, (ROW()-2)*8, 0, 8, 1)) -> 240 | T2: =SUM(OFFSET('zejscia WORK 2'!$G$2, (ROW()-2)*8, 0, 8, 1)) -> 127 | U2: =SUM(OFFSET('zejscia WORK 2'!$H$2, (ROW()-2)*8, 0, 8, 1)) -> 10 | V2: =SUM(OFFSET('zejscia WORK 2'!$I$2, (ROW()-2)*8, 0, 8, 1)) -> 137
A3: 2 | B3: 42421 | C3: 0 | D3: 4 | E3: (B)Nextgen, standard z zaworem | F3: =40*0.75 -> 30 | G3: 21 | H3: 1 | I3: 22 | J3: 9 | M3: 21.02.2016 -2 | N3: 2 | P3: =(T3/V3)*100 -> 92.54386 | Q3: =(V3/S3)*100 -> 95 | S3: =SUM(OFFSET('zejscia WORK 2'!$F$2, (ROW()-2)*8, 0, 8, 1)) -> 240 | T3: =SUM(OFFSET('zejscia WORK 2'!$G$2, (ROW()-2)*8, 0, 8, 1)) -> 211 | U3: =SUM(OFFSET('zejscia WORK 2'!$H$2, (ROW()-2)*8, 0, 8, 1)) -> 17 | V3: =SUM(OFFSET('zejscia WORK 2'!$I$2, (ROW()-2)*8, 0, 8, 1)) -> 228
A4: 3 | B4: 42421 | C4: 0 | D4: 4 | E4: (B)Nextgen, standard z zaworem | F4: =40*0.75 -> 30 | G4: 15 | H4: 2 | I4: 17 | J4: 15 | M4: 21.02.2016 -3 | N4: 3 | P4: =(T4/V4)*100 -> 93.38843 | Q4: =(V4/S4)*100 -> 100.83333 | S4: =SUM(OFFSET('zejscia WORK 2'!$F$2, (ROW()-2)*8, 0, 8, 1)) -> 240 | T4: =SUM(OFFSET('zejscia WORK 2'!$G$2, (ROW()-2)*8, 0, 8, 1)) -> 226 | U4: =SUM(OFFSET('zejscia WORK 2'!$H$2, (ROW()-2)*8, 0, 8, 1)) -> 16 | V4: =SUM(OFFSET('zejscia WORK 2'!$I$2, (ROW()-2)*8, 0, 8, 1)) -> 242
A5: 4 | B5: 42421 | C5: 0 | D5: 4 | E5: (B)Nextgen, standard z zaworem | F5: =40*0.75 -> 30 | G5: 7 | H5: 2 | I5: 9 | J5: 23 | M5: 22.02.2016 -1 | N5: 1 | P5: =(T5/V5)*100 -> 91.880342 | Q5: =(V5/S5)*100 -> 97.5 | S5: =SUM(OFFSET('zejscia WORK 2'!$F$2, (ROW()-2)*8, 0, 8, 1)) -> 240 | T5: =SUM(OFFSET('zejscia WORK 2'!$G$2, (ROW()-2)*8, 0, 8, 1)) -> 215 | U5: =SUM(OFFSET('zejscia WORK 2'!$H$2, (ROW()-2)*8, 0, 8, 1)) -> 19 | V5: =SUM(OFFSET('zejscia WORK 2'!$I$2, (ROW()-2)*8, 0, 8, 1)) -> 234
A6: 5 | B6: 42421 | C6: 0 | D6: 4 | E6: (B)Nextgen, standard z zaworem | F6: =40*0.75 -> 30 | G6: 15 | H6: 1 | I6: 16 | J6: 15 | M6: 22.02.2016 -2 | N6: 2 | P6: =(T6/V6)*100 -> 95.121951 | Q6: =(V6/S6)*100 -> 17.083333 | S6: =SUM(OFFSET('zejscia WORK 2'!$F$2, (ROW()-2)*8, 0, 8, 1)) -> 240 | T6: =SUM(OFFSET('zejscia WORK 2'!$G$2, (ROW()-2)*8, 0, 8, 1)) -> 39 | U6: =SUM(OFFSET('zejscia WORK 2'!$H$2, (ROW()-2)*8, 0, 8, 1)) -> 2 | V6: =SUM(OFFSET('zejscia WORK 2'!$I$2, (ROW()-2)*8, 0, 8, 1)) -> 41
A7: 6 | B7: 42421 | C7: 0 | D7: 4 | E7: (B)Nextgen, standard z zaworem | F7: =40*0.75 -> 30 | G7: 8 | H7: 0 | I7: 8 | J7: 22 | M7: 22.02.2016 -3 | N7: 3 | P7: =(T7/V7)*100 -> 94.623656 | Q7: =(V7/S7)*100 -> 38.75 | S7: =SUM(OFFSET('zejscia WORK 2'!$F$2, (ROW()-2)*8, 0, 8, 1)) -> 240 | T7: =SUM(OFFSET('zejscia WORK 2'!$G$2, (ROW()-2)*8, 0, 8, 1)) -> 88 | U7: =SUM(OFFSET('zejscia WORK 2'!$H$2, (ROW()-2)*8, 0, 8, 1)) -> 5 | V7: =SUM(OFFSET('zejscia WORK 2'!$I$2, (ROW()-2)*8, 0, 8, 1)) -> 93
A8: 7 | B8: 42421 | C8: 0 | D8: 4 | E8: (B)Nextgen, standard z zaworem | F8: =40*0.75 -> 30 | G8: 11 | H8: 0 | I8: 11 | J8: 19 | M8: 23.02.2016 -1 | N8: 1 | P8: =(T8/V8)*100 -> 94.360902 | Q8: =(V8/S8)*100 -> 110.83333 | S8: =SUM(OFFSET('zejscia WORK 2'!$F$2, (ROW()-2)*8, 0, 8, 1)) -> 240 | T8: =SUM(OFFSET('zejscia WORK 2'!$G$2, (ROW()-2)*8, 0, 8, 1)) -> 251 | U8: =SUM(OFFSET('zejscia WORK 2'!$H$2, (ROW()-2)*8, 0, 8, 1)) -> 15 | V8: =SUM(OFFSET('zejscia WORK 2'!$I$2, (ROW()-2)*8, 0, 8, 1)) -> 266
A9: 8 | B9: 42421 | C9: 0 | D9: 4 | E9: (B)Nextgen, standard z zaworem | F9: =40*0.75 -> 30 | G9: 23 | H9: 2 | I9: 25 | J9: 7 | M9: 23.02.2016 -2 | N9: 2 | P9: =(T9/V9)*100 -> 93.488372 | Q9: =(V9/S9)*100 -> 89.583333 | S9: =SUM(OFFSET('zejscia WORK 2'!$F$2, (ROW()-2)*8, 0, 8, 1)) -> 240 | T9: =SUM(OFFSET('zejscia WORK 2'!$G$2, (ROW()-2)*8, 0, 8, 1)) -> 201 | U9: =SUM(OFFSET('zejscia WORK 2'!$H$2, (ROW()-2)*8, 0, 8, 1)) -> 14 | V9: =SUM(OFFSET('zejscia WORK 2'!$I$2, (ROW()-2)*8, 0, 8, 1)) -> 215
A10: 9 | B10: 42421.62 | C10: 0.62 | D10: 4 | E10: (A)Bez zaworu | F10: =40*0.75 -> 30 | G10: 21 | H10: 2 | I10: 23 | J10: 9 | M10: 23.02.2016 -3 | N10: 3 | P10: =(T10/V10)*100 -> 88.571429 | Q10: =(V10/S10)*100 -> 72.916667 | S10: =SUM(OFFSET('zejscia WORK 2'!$F$2, (ROW()-2)*8, 0, 8, 1)) -> 240 | T10: =SUM(OFFSET('zejscia WORK 2'!$G$2, (ROW()-2)*8, 0, 8, 1)) -> 155 | U10: =SUM(OFFSET('zejscia WORK 2'!$H$2, (ROW()-2)*8, 0, 8, 1)) -> 20 | V10: =SUM(OFFSET('zejscia WORK 2'!$I$2, (ROW()-2)*8, 0, 8, 1)) -> 175
A11: 10 | B11: 42421.609 | C11: 0.60887731 | D11: 4 | E11: (A)Bez zaworu | F11: =40*0.75 -> 30 | G11: 36 | H11: 2 | I11: 38 | J11: -6 | M11: 24.02.2016 -1 | N11: 1 | P11: =(T11/V11)*100 -> 92.405063 | Q11: =(V11/S11)*100 -> 98.75 | S11: =SUM(OFFSET('zejscia WORK 2'!$F$2, (ROW()-2)*8, 0, 8, 1)) -> 240 | T11: =SUM(OFFSET('zejscia WORK 2'!$G$2, (ROW()-2)*8, 0, 8, 1)) -> 219 | U11: =SUM(OFFSET('zejscia WORK 2'!$H$2, (ROW()-2)*8, 0, 8, 1)) -> 18 | V11: =SUM(OFFSET('zejscia WORK 2'!$I$2, (ROW()-2)*8, 0, 8, 1)) -> 237
A12: 11 | B12: 42421.625 | C12: 0.62501157 | D12: 4 | E12: (A)Bez zaworu | F12: =40*0.75 -> 30 | G12: 21 | H12: 4 | I12: 25 | J12: 9 | M12: 24.02.2016 -2 | N12: 2 | P12: =(T12/V12)*100 -> 90.526316 | Q12: =(V12/S12)*100 -> 39.583333 | S12: =SUM(OFFSET('zejscia WORK 2'!$F$2, (ROW()-2)*8, 0, 8, 1)) -> 240 | T12: =SUM(OFFSET('zejscia WORK 2'!$G$2, (ROW()-2)*8, 0, 8, 1)) -> 86 | U12: =SUM(OFFSET('zejscia WORK 2'!$H$2, (ROW()-2)*8, 0, 8, 1)) -> 9 | V12: =SUM(OFFSET('zejscia WORK 2'!$I$2, (ROW()-2)*8, 0, 8, 1)) -> 95
A13: 12 | B13: 42421.646 | C13: 0.64572917 | D13: 4 | E13: (A)Bez zaworu | F13: =40*0.75 -> 30 | G13: 13 | H13: 3 | I13: 16 | J13: 17 | M13: 24.02.2016 -3 | N13: 3 | P13: =(T13/V13)*100 -> 95.020747 | Q13: =(V13/S13)*100 -> 100.41667 | S13: =SUM(OFFSET('zejscia WORK 2'!$F$2, (ROW()-2)*8, 0, 8, 1)) -> 240 | T13: =SUM(OFFSET('zejscia WORK 2'!$G$2, (ROW()-2)*8, 0, 8, 1)) -> 229 | U13: =SUM(OFFSET('zejscia WORK 2'!$H$2, (ROW()-2)*8, 0, 8, 1)) -> 12 | V13: =SUM(OFFSET('zejscia WORK 2'!$I$2, (ROW()-2)*8, 0, 8, 1)) -> 241
... A22: 21 | B22: 42421.921 | C22: 0.9205787 | D22: 4 | E22: (A)Bez zaworu | F22: =40*0.75 -> 30 | G22: 32 | H22: 2 | I22: 34 | J22: -2 | M22: 27.02.2016 -3 | N22: 3 | P22: =(T22/V22)*100 -> 91.803279 | Q22: =(V22/S22)*100 -> 25.416667 | S22: =SUM(OFFSET('zejscia WORK 2'!$F$2, (ROW()-2)*8, 0, 8, 1)) -> 240 | T22: =SUM(OFFSET('zejscia WORK 2'!$G$2, (ROW()-2)*8, 0, 8, 1)) -> 56 | U22: =SUM(OFFSET('zejscia WORK 2'!$H$2, (ROW()-2)*8, 0, 8, 1)) -> 5 | V22: =SUM(OFFSET('zejscia WORK 2'!$I$2, (ROW()-2)*8, 0, 8, 1)) -> 61
A23: 22 | B23: 42421.921 | C23: 0.920625 | D23: 4 | E23: (A)Bez zaworu | F23: =40*0.75 -> 30 | G23: 35 | H23: 0 | I23: 35 | J23: -5
A24: 23 | B24: 42421.921 | C24: 0.92065972 | D24: 4 | E24: (A)Bez zaworu | F24: =40*0.75 -> 30 | G24: 38 | H24: 1 | I24: 39 | J24: -8
A25: 24 | B25: 42421.921 | C25: 0.9206713 | D25: 4 | E25: (A)Bez zaworu | F25: =40*0.75 -> 30 | G25: 30 | H25: 1 | I25: 31 | J25: 0
A26: 25 | B26: 42422.537 | C26: 0.53748843 | D26: 4 | E26: (B)Nextgen, standard z zaworem | F26: =40*0.75 -> 30 | G26: 29 | H26: 5 | I26: 34 | J26: 1
A27: 26 | B27: 42422.538 | C27: 0.53751157 | D27: 4 | E27: (B)Nextgen, standard z zaworem | F27: =40*0.75 -> 30 | G27: 38 | H27: 2 | I27: 40 | J27: -8
A28: 27 | B28: 42422.538 | C28: 0.53753472 | D28: 4 | E28: (B)Nextgen, standard z zaworem | F28: =40*0.75 -> 30 | G28: 34 | H28: 2 | I28: 36 | J28: -4
A29: 28 | B29: 42422.538 | C29: 0.53755787 | D29: 4 | E29: (B)Nextgen, standard z zaworem | F29: =40*0.75 -> 30 | G29: 14 | H29: 1 | I29: 15 | J29: 16
A30: 29 | B30: 42422.538 | C30: 0.53758102 | D30: 4 | E30: (B)Nextgen, standard z zaworem | F30: =40*0.75 -> 30 | G30: 29 | H30: 2 | I30: 31 | J30: 1
A31: 30 | B31: 42422.538 | C31: 0.53760417 | D31: 4 | E31: (B)Nextgen, standard z zaworem | F31: =40*0.75 -> 30 | G31: 28 | H31: 3 | I31: 31 | J31: 2
A32: 31 | B32: 42422.538 | C32: 0.53762731 | D32: 4 | E32: (B)Nextgen, standard z zaworem | F32: =40*0.75 -> 30 | G32: 29 | H32: 2 | I32: 31 | J32: 1
A33: 32 | B33: 42422.538 | C33: 0.53765046 | D33: 4 | E33: (B)Nextgen, standard z zaworem | F33: =40*0.75 -> 30 | G33: 14 | H33: 2 | I33: 16 | J33: 16
A34: 33 | B34: 42422.584 | C34: 0.58417824 | D34: 4 | E34: (A)Bez zaworu | F34: =40*0.75 -> 30 | G34: 15 | H34: 2 | I34: 17 | J34: 15
... A929: 928 | B929: 42480.251 | C929: 0.25071759 | D929: 4 | E929: Nextgen, standard | F929: =40*0.75 -> 30 | G929: 32 | H929: 2 | I929: 34 | J929: -2

Sheet Awarie WORK2
E1: Grupa_bledu | F1: Podgrupa_bledu | K1: Suma całego czasu straconego na przestoje w ciągu tygodnia 21.2.2016 - 28.02.2016 | L1: Suma całego czasu straconego na przestoje DUR (Awaria + przegląd_Serwis) w ciągu tygodnia21.2.2016 - 28.02.2016 | M1: problemy IT | N1: Problemy Jakość | O1: Ogólne linia | P1: szkolenia | Q1: Procent awari | R1: Procent IT | S1: Procent Jakości | T1: Procent Ogólny | U1: Procent szkolenia
A2: 42881.225 | B2: 42421 | C2: 0.74861111 | D2: 1700-1800 | E2: Ogolne_Linia | G2: przerwa od 17-40 do 18-00 | H2: 25 | I2: =ROUNDUP((H2*1.24), 0) -> 31 | J2: =ROUNDUP(H2*0.6, 0) -> 15 | K2: =SUM(H2:H108) -> 1865 | L2: 1005 | M2: 10 | N2: 5 | O2: 324 | P2: 75 | Q2: =(L2/K2)*100 -> 53.887399 | R2: =(M2/K2)*100 -> 0.53619303 | S2: =(N2/K2)*100 -> 0.26809651 | T2: =(O2/K2)*100 -> 17.372654 | U2: =(P2/K2)*100 -> 4.0214477 | V2: =SUM(Q2:U2) -> 76.085791
A3: 42881.112 | B3: 42421 | C3: 0.59930556 | D3: 1400-1500 | E3: Ogolne_Linia | F3: dodatkowa przerwa | G3: opóźnienie autobusu | H3: 25 | I3: =ROUNDUP((H3*1.24), 0) -> 31 | J3: =ROUNDUP(H3*0.6, 0) -> 15 | K3: Suma stracenego czasu | L3: Awarie | M3: IT | N3: Jakość | O3: Ogólne | P3: Szkolenia
A4: 42881.09 | B4: 42421 | C4: 0.58472222 | D4: 1400-1500 | E4: Ogolne_Linia | F4: dokładanie komponentów | G4: uzupełnienie śrub | H4: 2 | I4: =ROUNDUP((H4*1.24), 0) -> 3 | J4: =ROUNDUP(H4*0.6, 0) -> 2 | K4: =K2/60 -> 31.083333 | L4: =L2/60 -> 16.75 | M4: =M2/60 -> 0.16666667 | N4: =N2/60 -> 0.083333333 | O4: =O2/60 -> 5.4 | P4: =P2/60 -> 1.25
A5: 42881.227 | B5: 42421 | C5: 0.58402778 | D5: 1400-1500 | E5: Ogolne_Linia | F5: dokładanie komponentów | G5: uzupełnienie plyt, oringów | H5: 2 | I5: =ROUNDUP((H5*1.24), 0) -> 3 | J5: =ROUNDUP(H5*0.6, 0) -> 2
A6: 42880.833 | B6: 42421 | C6: 0.58333333 | D6: 1400-1500 | E6: Oczekwianie | F6: brakujący komponent | G6: brak szczelnych adapterów na stacji napraw M22 do korpusów11183826 | H6: 50 | I6: =ROUNDUP((H6*1.24), 0) -> 62 | J6: =ROUNDUP(H6*0.6, 0) -> 30
A7: 42880.717 | B7: 42421 | C7: 0.58194444 | D7: 1300-1400 | E7: Ogolne_Linia | F7: dokładanie komponentów | G7: uzupełnienie śrub | H7: 4 | I7: =ROUNDUP((H7*1.24), 0) -> 5 | J7: =ROUNDUP(H7*0.6, 0) -> 3
A8: 42880.699 | B8: 42421 | C8: 0.57916667 | D8: 1300-1400 | E8: Ogolne_Linia | F8: zapełnianie linii | H8: 19 | I8: =ROUNDUP((H8*1.24), 0) -> 24 | J8: =ROUNDUP(H8*0.6, 0) -> 12
A9: 42880.669 | B9: 42421 | C9: 0.57916667 | D9: 1300-1400 | E9: Ogolne_Linia | F9: rework motoru | H9: 13 | I9: =ROUNDUP((H9*1.24), 0) -> 17 | J9: =ROUNDUP(H9*0.6, 0) -> 8
A10: 42880.541 | B10: 42421 | C10: 0.99375 | D10: Invalid Time | E10: Przegląd_Serwis | G10: przeglad dur, nie idzie SMAR st 20 | H10: 34 | I10: =ROUNDUP((H10*1.24), 0) -> 43 | J10: =ROUNDUP(H10*0.6, 0) -> 21
A11: 42880.495 | B11: 42421 | C11: 0.97569444 | D11: Invalid Time | E11: Awaria | F11: stacja 60 - KUKA | G11: zawieszenie robota | H11: 19 | I11: =ROUNDUP((H11*1.24), 0) -> 24 | J11: =ROUNDUP(H11*0.6, 0) -> 12
A12: 42880.479 | B12: 42421 | C12: 0.95 | D12: 2200-2300 | E12: Przegląd_Serwis | F12: wymiana filtra | G12: wymiana filtru hg003 | H12: 25 | I12: =ROUNDUP((H12*1.24), 0) -> 31 | J12: =ROUNDUP(H12*0.6, 0) -> 15
A13: 42880.434 | B13: 42421 | C13: 0.92013889 | D13: 2200-2300 | E13: Przegląd_Serwis | G13: puszanie testera | H13: 7 | I13: =ROUNDUP((H13*1.24), 0) -> 9 | J13: =ROUNDUP(H13*0.6, 0) -> 5
A14: 42880.375 | B14: 42421 | C14: 0.76041667 | D14: 1800-1900 | E14: Awaria | F14: stacja 60 - KUKA | G14: KUKA upuśćila kolejny motor ze st. Napraw na podłodze | H14: 19 | I14: =ROUNDUP((H14*1.24), 0) -> 24 | J14: =ROUNDUP(H14*0.6, 0) -> 12
A15: 42880.311 | B15: 42421 | C15: 0.71736111 | D15: 1700-1800 | E15: Awaria | F15: stacja 60 - KUKA | G15: KUKA upuśćila kolejny motor ze st. Napraw na podłodze | H15: 19 | I15: =ROUNDUP((H15*1.24), 0) -> 24 | J15: =ROUNDUP(H15*0.6, 0) -> 12
A16: 42880.31 | B16: 42421 | C16: 0.70555556 | D16: 1600-1700 | E16: Awaria | F16: stacja 60 - KUKA | G16: KUKA UPUŚĆIŁA MOTOR na podłodze | H16: 13 | I16: =ROUNDUP((H16*1.24), 0) -> 17 | J16: =ROUNDUP(H16*0.6, 0) -> 8
A17: 42880.172 | B17: 42421 | C17: 0.68819444 | D17: 1600-1700 | E17: Awaria | F17: stacja 60 - KUKA | G17: KUKA UPUŚĆIŁA MOTOR na podłodze | H17: 13 | I17: =ROUNDUP((H17*1.24), 0) -> 17 | J17: =ROUNDUP(H17*0.6, 0) -> 8
A18: 42880.149 | B18: 42421 | C18: 0.59097222 | D18: 1400-1500 | E18: Przegląd_Serwis | F18: interwencja DUR | G18: DUR na linii,trwa naprawa | H18: 50 | I18: =ROUNDUP((H18*1.24), 0) -> 62 | J18: =ROUNDUP(H18*0.6, 0) -> 30
A19: 42880.148 | B19: 42421 | C19: 0.59097222 | D19: 1400-1500 | E19: Przegląd_Serwis | F19: interwencja DUR | G19: DUR na linii,trwa naprawa | H19: 13 | I19: =ROUNDUP((H19*1.24), 0) -> 17 | J19: =ROUNDUP(H19*0.6, 0) -> 8
A20: 42880.919 | B20: 42421 | C20: 0.58541667 | D20: 1400-1500 | E20: Przegląd_Serwis | F20: interwencja DUR | G20: DUR na linii,trwa naprawa | H20: 56 | I20: =ROUNDUP((H20*1.24), 0) -> 70 | J20: =ROUNDUP(H20*0.6, 0) -> 34
A21: 42880.908 | B21: 42421 | C21: 0.58472222 | D21: 1400-1500 | E21: Przegląd_Serwis | F21: interwencja DUR | G21: DUR na linii,trwa naprawa | H21: 13 | I21: =ROUNDUP((H21*1.24), 0) -> 17 | J21: =ROUNDUP(H21*0.6, 0) -> 8
A22: 42880.656 | B22: 42421 | C22: 0.58402778 | D22: 1400-1500 | E22: Awaria | F22: stacja 50 - test szczelności | G22: przeddłużony test szczelności od 100 -160 sekund | H22: 31 | I22: =ROUNDUP((H22*1.24), 0) -> 39 | J22: =ROUNDUP(H22*0.6, 0) -> 19
A23: 42880.605 | B23: 42421 | C23: 0.58333333 | D23: 1400-1500 | E23: Przegląd_Serwis | F23: interwencja DUR | G23: DUR na linii,trwa naprawa | H23: 31 | I23: =ROUNDUP((H23*1.24), 0) -> 39 | J23: =ROUNDUP(H23*0.6, 0) -> 19
A24: 42880.392 | B24: 42421 | C24: 0.58263889 | D24: 1300-1400 | E24: Przegląd_Serwis | F24: interwencja DUR | G24: DUR na linii,trwa naprawa | H24: 22 | I24: =ROUNDUP((H24*1.24), 0) -> 28 | J24: =ROUNDUP(H24*0.6, 0) -> 14
A25: 42880.247 | B25: 42421 | C25: 0.58263889 | D25: 1300-1400 | E25: Awaria | F25: stacja 50 - test szczelności | G25: przeddłużony test szczelności od 100 -147 sekund | H25: 19 | I25: =ROUNDUP((H25*1.24), 0) -> 24 | J25: =ROUNDUP(H25*0.6, 0) -> 12
... A27: 42879.658 | B27: 42421 | C27: 0.57986111 | D27: 1300-1400 | E27: Awaria | F27: stacja 50 - test szczelności | G27: przeddłużony test szczelności od 100 -147 sekund | H27: 31 | I27: =ROUNDUP((H27*1.24), 0) -> 39 | J27: =ROUNDUP(H27*0.6, 0) -> 19
A28: 42879.5 | B28: 42422 | C28: 0.73402778 | D28: 1700-1800 | E28: Ogolne_Linia | G28: przerwa | H28: 25 | I28: =ROUNDUP((H28*1.24), 0) -> 31 | J28: =ROUNDUP(H28*0.6, 0) -> 15
A29: 42879.375 | B29: 42422 | C29: 0.58125 | D29: 1300-1400 | E29: Ogolne_Linia | G29: sprzątanie linii | H29: 7 | I29: =ROUNDUP((H29*1.24), 0) -> 9 | J29: =ROUNDUP(H29*0.6, 0) -> 5
A30: 42879.213 | B30: 42422 | C30: 0.57013889 | D30: 1300-1400 | E30: Szkolenie_Spotkanie | F30: spotkanie z koordynatorem | H30: 25 | I30: =ROUNDUP((H30*1.24), 0) -> 31 | J30: =ROUNDUP(H30*0.6, 0) -> 15
A31: 42879.917 | B31: 42422 | C31: 0.55138889 | D31: 1300-1400 | E31: Ogolne_Linia | G31: problematyczny pomiar cardana 11184809 11:46 | H31: 4 | I31: =ROUNDUP((H31*1.24), 0) -> 5 | J31: =ROUNDUP(H31*0.6, 0) -> 3
A32: 42879.584 | B32: 42422 | C32: 0.55 | D32: 1300-1400 | E32: Ogolne_Linia | F32: dokładanie komponentów | G32: śruby+o-ringi | H32: 3 | I32: =ROUNDUP((H32*1.24), 0) -> 4 | J32: =ROUNDUP(H32*0.6, 0) -> 2
A33: 42879.517 | B33: 42422 | C33: 0.54930556 | D33: 1300-1400 | E33: IT_Problem | G33: problem z licenziej EXCEL 11:15 | H33: 13 | I33: =ROUNDUP((H33*1.24), 0) -> 17 | J33: =ROUNDUP(H33*0.6, 0) -> 8
A34: 42879.249 | B34: 42422 | C34: 0.54861111 | D34: 1300-1400 | E34: Ogolne_Linia | F34: dokładanie komponentów | G34: w 10:32 | H34: 2 | I34: =ROUNDUP((H34*1.24), 0) -> 3 | J34: =ROUNDUP(H34*0.6, 0) -> 2
A35: 42878.921 | B35: 42422 | C35: 0.54652778 | D35: 1300-1400 | E35: Szkolenie_Spotkanie | F35: trening operatora | G35: od 10:00-14:00 po 10 min w godzine | H35: 13 | I35: =ROUNDUP((H35*1.24), 0) -> 17 | J35: =ROUNDUP(H35*0.6, 0) -> 8
A36: 42878.906 | B36: 42422 | C36: 0.54583333 | D36: 1300-1400 | E36: Ogolne_Linia | F36: dodatkowa przerwa | G36: PRZERWA 9:40-10:00 | H36: 25 | I36: =ROUNDUP((H36*1.24), 0) -> 31 | J36: =ROUNDUP(H36*0.6, 0) -> 15
A37: 42878.865 | B37: 42422 | C37: 0.53958333 | D37: 1200-1300 | E37: Jakość | F37: selekcja komponentów | G37: selekcja+uzupelnienie plut 9:00 | H37: 7 | I37: =ROUNDUP((H37*1.24), 0) -> 9 | J37: =ROUNDUP(H37*0.6, 0) -> 5
A38: 42878.802 | B38: 42422 | C38: 0.53888889 | D38: 1200-1300 | E38: Ogolne_Linia | F38: dokładanie komponentów | G38: uzupelnienie śrub 8:31 | H38: 2 | I38: =ROUNDUP((H38*1.24), 0) -> 3 | J38: =ROUNDUP(H38*0.6, 0) -> 2
A39: 42878.662 | B39: 42422 | C39: 0.53819444 | D39: 1200-1300 | E39: Ogolne_Linia | F39: dokładanie komponentów | G39: uzupelnienie śrub 7:00 | H39: 3 | I39: =ROUNDUP((H39*1.24), 0) -> 4 | J39: =ROUNDUP(H39*0.6, 0) -> 2
A40: 42878.608 | B40: 42422 | C40: 0.81944444 | D40: 1900-2000 | E40: Awaria | F40: stacja 41 - dokręcanie śrub | G40: AWARIA st.41 od god.16-30 do konca zmieny.DUR nie może tego naprawić | H40: 75 | I40: =ROUNDUP((H40*1.24), 0) -> 93 | J40: =ROUNDUP(H40*0.6, 0) -> 45
A41: 42878.592 | B41: 42422 | C41: 0.75069444 | D41: 1800-1900 | E41: Awaria | F41: stacja 41 - dokręcanie śrub | G41: naprawa st.41,paletka zatrzymuje się między st.40 i st.41 , | H41: 75 | I41: =ROUNDUP((H41*1.24), 0) -> 93
...

Sheet czas awarii
G1: Suma czasu awari | H1: Czas na zmianę | I1: % czasu przestoju | S1: Grupa_bledu | T1: Podgrupa_bledu
A2: 42421 | B2: Invalid Time | C2: 27 | F2: 21.02.2026 1 | G2: =SUM(C44:C51) -> 175 | I2: =(G2/$H$2)*100 -> #DIV/0! | P2: 42421 | Q2: 0.99375 | R2: Invalid Time | S2: Przegląd_Serwis | U2: przeglad dur, nie idzie SMAR st 20 | V2: 27
A3: 42421 | B3: Invalid Time | C3: 15 | F3: 21.02.2026 2 | G3: =SUM(C44:C45) -> 15 | I3: =(G3/$H$2)*100 -> #DIV/0! | P3: 42421 | Q3: 0.97569444 | R3: Invalid Time | S3: Awaria | T3: stacja 60 - KUKA | U3: zawieszenie robota | V3: 15
A4: 42421 | B4: 2200-2300 | C4: 20 | F4: 21.02.2026 3 | G4: =SUM(C45,C58,C57,C56) -> 10 | I4: =(G4/$H$2)*100 -> #DIV/0! | P4: 42421 | Q4: 0.95 | R4: 2200-2300 | S4: Przegląd_Serwis | T4: wymiana filtra | U4: wymiana filtru hg003 | V4: 20
A5: 42421 | B5: 2200-2300 | C5: 5 | F5: 22.02.2026 1 | G5: 0 | I5: =(G5/$H$2)*100 -> #DIV/0! | P5: 42421 | Q5: 0.92013889 | R5: 2200-2300 | S5: Przegląd_Serwis | U5: puszanie testera | V5: 5
A6: 42421 | B6: 1800-1900 | C6: 15 | F6: 22.02.2026 2 | G6: 0 | I6: =(G6/$H$2)*100 -> #DIV/0! | P6: 42421 | Q6: 0.76041667 | R6: 1800-1900 | S6: Awaria | T6: stacja 60 - KUKA | U6: KUKA upuśćila kolejny motor ze st. Napraw na podłodze | V6: 15
A7: 42421 | B7: 1700-1800 | C7: 15 | F7: 22.02.2026 3 | G7: =SUM(C46:C50) -> 130 | I7: =(G7/$H$2)*100 -> #DIV/0! | P7: 42421 | Q7: 0.71736111 | R7: 1700-1800 | S7: Awaria | T7: stacja 60 - KUKA | U7: KUKA upuśćila kolejny motor ze st. Napraw na podłodze | V7: 15
A8: 42421 | B8: 1600-1700 | C8: 10 | F8: 23.02.2026 1 | G8: 0 | I8: =(G8/$H$2)*100 -> #DIV/0! | P8: 42421 | Q8: 0.70555556 | R8: 1600-1700 | S8: Awaria | T8: stacja 60 - KUKA | U8: KUKA UPUŚĆIŁA MOTOR na podłodze | V8: 10
A9: 42421 | B9: 1600-1700 | C9: 10 | F9: 23.02.2026 2 | G9: 0 | I9: =(G9/$H$2)*100 -> #DIV/0! | P9: 42421 | Q9: 0.68819444 | R9: 1600-1700 | S9: Awaria | T9: stacja 60 - KUKA | U9: KUKA UPUŚĆIŁA MOTOR na podłodze | V9: 10
A10: 42421 | B10: 1400-1500 | C10: 40 | F10: 23.02.2026 3 | G10: =SUM(C51) -> 30 | I10: =(G10/$H$2)*100 -> #DIV/0! | P10: 42421 | Q10: 0.59097222 | R10: 1400-1500 | S10: Przegląd_Serwis | T10: interwencja DUR | U10: DUR na linii,trwa naprawa | V10: 40
A11: 42421 | B11: 1400-1500 | C11: 10 | F11: 24.02.2026 1 | G11: =SUM(C43:C49) -> 127 | I11: =(G11/$H$2)*100 -> #DIV/0! | P11: 42421 | Q11: 0.59097222 | R11: 1400-1500 | S11: Przegląd_Serwis | T11: interwencja DUR | U11: DUR na linii,trwa naprawa | V11: 10
A12: 42421 | B12: 1400-1500 | C12: 45 | F12: 24.02.2026 2 | G12: =SUM(C37:C44) -> 94 | I12: =(G12/$H$2)*100 -> #DIV/0! | P12: 42421 | Q12: 0.58541667 | R12: 1400-1500 | S12: Przegląd_Serwis | T12: interwencja DUR | U12: DUR na linii,trwa naprawa | V12: 45
A13: 42421 | B13: 1400-1500 | C13: 10 | F13: 24.02.2026 3 | G13: =SUM(C54) -> 10 | I13: =(G13/$H$2)*100 -> #DIV/0! | P13: 42421 | Q13: 0.58472222 | R13: 1400-1500 | S13: Przegląd_Serwis | T13: interwencja DUR | U13: DUR na linii,trwa naprawa | V13: 10
A14: 42421 | B14: 1400-1500 | C14: 25 | F14: 25.02.2026 1 | G14: =SUM(C35:C39) -> 125 | I14: =(G14/$H$2)*100 -> #DIV/0! | P14: 42421 | Q14: 0.58402778 | R14: 1400-1500 | S14: Awaria | T14: stacja 50 - test szczelności | U14: przeddłużony test szczelności od 100 -160 sekund | V14: 25
A15: 42421 | B15: 1400-1500 | C15: 25 | F15: 25.02.2026 2 | G15: =SUM(C31:C36) -> 82 | I15: =(G15/$H$2)*100 -> #DIV/0! | P15: 42421 | Q15: 0.58333333 | R15: 1400-1500 | S15: Przegląd_Serwis | T15: interwencja DUR | U15: DUR na linii,trwa naprawa | V15: 25
A16: 42421 | B16: 1300-1400 | C16: 17 | F16: 25.02.2026 3 | G16: =SUM(C44,C32) -> 15 | I16: =(G16/$H$2)*100 -> #DIV/0! | P16: 42421 | Q16: 0.58263889 | R16: 1300-1400 | S16: Przegląd_Serwis | T16: interwencja DUR | U16: DUR na linii,trwa naprawa | V16: 17
A17: 42421 | B17: 1300-1400 | C17: 15 | F17: 26.05.2017 1 | G17: =SUM(C31:C32) -> 20 | I17: =(G17/$H$2)*100 -> #DIV/0! | P17: 42421 | Q17: 0.58263889 | R17: 1300-1400 | S17: Awaria | T17: stacja 50 - test szczelności | U17: przeddłużony test szczelności od 100 -147 sekund | V17: 15
A18: 42421 | B18: 1300-1400 | C18: 2 | F18: 26.05.2017 2 | G18: =SUM(C31:C32) -> 20 | I18: =(G18/$H$2)*100 -> #DIV/0! | P18: 42421 | Q18: 0.57986111 | R18: 1300-1400 | S18: Awaria | T18: stacja 40 - montaż śrub | U18: problem z testem wizijnym na cover film. 11185636 | V18: 2
A19: 42421 | B19: 1300-1400 | C19: 25 | F19: 26.05.2017 3 | G19: =SUM(C37) -> 45 | I19: =(G19/$H$2)*100 -> #DIV/0! | P19: 42421 | Q19: 0.57986111 | R19: 1300-1400 | S19: Awaria | T19: stacja 50 - test szczelności | U19: przeddłużony test szczelności od 100 -147 sekund | V19: 25
A20: 42422 | B20: 1900-2000 | C20: 60 | F20: 27.05.2017 1 | G20: =SUM(C25:C31) -> 113 | I20: =(G20/$H$2)*100 -> #DIV/0! | P20: 42422 | Q20: 0.81944444 | R20: 1900-2000 | S20: Awaria | T20: stacja 41 - dokręcanie śrub | U20: AWARIA st.41 od god.16-30 do konca zmieny.DUR nie może tego naprawić | V20: 60
A21: 42422 | B21: 1800-1900 | C21: 60 | F21: 27.05.2017 2 | G21: =SUM(C23:C26) -> 75 | I21: =(G21/$H$2)*100 -> #DIV/0! | P21: 42422 | Q21: 0.75069444 | R21: 1800-1900 | S21: Awaria | T21: stacja 41 - dokręcanie śrub | U21: naprawa st.41,paletka zatrzymuje się między st.40 i st.41 , | V21: 60
A22: 42422 | B22: 1700-1800 | C22: 40 | F22: 27.05.2017 3 | G22: =SUM(C36:C38) -> 85 | H22: 450 | I22: =(G22/$H$2)*100 -> #DIV/0! | P22: 42422 | Q22: 0.72291667 | R22: 1700-1800 | S22: Awaria | T22: stacja 41 - dokręcanie śrub | U22: naprawa st.41,paletka zatrzymuje się między st.40 i st.41 , | V22: 40
A23: 42422 | B23: 1600-1700 | C23: 22 | P23: 42422 | Q23: 0.69305556 | R23: 1600-1700 | S23: Awaria | T23: stacja 41 - dokręcanie śrub | U23: zawieszenie st.41,czekanie na DUR | V23: 22
A24: 42422 | B24: 1600-1700 | C24: 13 | P24: 42422 | Q24: 0.66666667 | R24: 1600-1700 | S24: Awaria | T24: stacja 30 - montaż silnika | U24: Nie dziala test wizijny,czekanie na DUR | V24: 13
A25: 42422 | B25: 1500-1600 | C25: 20 | P25: 42422 | Q25: 0.65347222 | R25: 1500-1600 | S25: Awaria | T25: stacja 30 - montaż silnika | U25: nie dziala test wizijny,czekanie na DUR | V25: 20
A26: 42422 | B26: 1500-1600 | C26: 20 | P26: 42422 | Q26: 0.62777778 | R26: 1500-1600 | S26: Awaria | T26: stacja 60 - KUKA | U26: Zawieszenie Kuki,naprawa przes tehnologa | V26: 20
A27: 42422 | B27: 1400-1500 | C27: 23 | P27: 42422 | Q27: 0.60902778 | R27: 1400-1500 | S27: Awaria | T27: stacja 60 - KUKA | U27: Zawieszenie Kuki,naprawa przes tehnologa | V27: 23
A28: 42422 | B28: 1300-1400 | C28: 10 | P28: 42422 | Q28: 0.55069444 | R28: 1300-1400 | S28: Awaria | T28: stacja 60 - KUKA | U28: zawieszenie robota + szkolenie DUR 11:45 | V28: 10
A29: 42422 | B29: 1200-1300 | C29: 15 | P29: 42422 | Q29: 0.53958333 | R29: 1200-1300 | S29: Przegląd_Serwis | T29: wymiana papieru w drukarce | U29: Wymiana etykiet i kalibracja, dostosowanie wydruku 09:00:00 | V29: 15
A30: 42422 | B30: 0000-0100 | C30: 15 | P30: 42422 | Q30: 0.039583333 | R30: 0000-0100 | S30: Awaria | T30: stacja 60 - KUKA | U30: zawieszenie robota | V30: 15
A31: 42423 | B31: 0900-1000 | C31: 10 | P31: 42423 | Q31: 0.39166667 | R31: 0900-1000 | S31: Przegląd_Serwis | T31: praca technologa | U31: naprawa przez tehnologa Mikos P. | V31: 10
A32: 42423 | B32: 0900-1000 | C32: 10 | P32: 42423 | Q32: 0.39166667 | R32: 0900-1000 | S32: Przegląd_Serwis | T32: praca technologa | U32: naprawa przez tehnologa Mikos P. | V32: 10
A33: 42423 | B33: 0900-1000 | C33: 1 | P33: 42423 | Q33: 0.39027778 | R33: 0900-1000 | S33: Awaria | T33: stacja 20 - praska | U33: puszczenie ISIR i powa | V33: 1
A34: 42423 | B34: 0900-1000 | C34: 1 | P34: 42423 | Q34: 0.39027778 | R34: 0900-1000 | S34: Awaria | T34: stacja 20 - praska | U34: puszczenie ISIR i powa | V34: 1
... A40: 42424 | B40: 1600-1700 | C40: 10 | P40: 42424 | Q40: 0.70069444 | R40: 1600-1700 | S40: Przegląd_Serwis | T40: wymiana filtra | U40: wymina filtra HQ 020 | V40: 10
A41: 42424 | B41: 1400-1500 | C41: 7 | P41: 42424 | Q41: 0.61944444 | R41: 1400-1500 | S41: Awaria | U41: awaria st.41 | V41: 7
A42: 42424 | B42: 1200-1300 | C42: 5 | P42: 42424 | Q42: 0.52916667 | R42: 1200-1300 | S42: Awaria | T42: stacja 60 - KUKA | U42: zawieszenie robota | V42: 5
A43: 42424 | B43: 1100-1200 | C43: 2 | P43: 42424 | Q43: 0.48333333 | R43: 1100-1200 | S43: Awaria | T43: stacja 10 - załadunek paletki | U43: blędnyj pomiar cardana 11184906 | V43: 2
A44: 42424 | B44: 1100-1200 | C44: 5 | P44: 42424 | Q44: 0.46805556 | R44: 1100-1200 | S44: Awaria | T44: stacja 20 - praska | U44: zawieszenie | V44: 5
A45: 42424 | B45: 0900-1000 | C45: 10 | P45: 42424 | Q45: 0.37569444 | R45: 0900-1000 | S45: Przegląd_Serwis | T45: praca technologa | U45: Mikos P. | V45: 10
...

Sheet dashboards
C64: % czasu przestoju | D64: FPY | E64: Wszystkie zmontowane / CEL
A65: 21 | B65: 19.05.2017 1 | C65: 50 | D65: 76.890756 | E65: 50.773333
A66: 20 | B66: 19.05.2017 2 | C66: 17.333333 | D66: 91.428571 | E66: 61.707989
A67: 19 | B67: 19.05.2017 3 | C67: 4.4444444 | D67: 96.529284 | E67: 98.346667
A68: 18 | B68: 20.05.2017 1 | C68: 0 | D68: 97.552448 | E68: 61.013333
A69: 17 | B69: 20.05.2017 2 | C69: 0 | D69: 93.686869 | E69: 84.48
A70: 16 | B70: 20.05.2017 3 | C70: 34.222222 | D70: 91.153846 | E70: 75.090253
A71: 15 | B71: 21.05.2017 1 | C71: 0 | D71: 93.872549 | E71: 90.165746
A72: 14 | B72: 21.05.2017 2 | C72: 0 | D72: 95.882353 | E72: 45.033113
A73: 13 | B73: 21.05.2017 3 | C73: 13.333333 | D73: 92.75766 | E73: 76.586667
A74: 12 | B74: 22.05.2017 1 | C74: 63.111111 | D74: 97.002725 | E74: 78.293333
A75: 11 | B75: 22.05.2017 2 | C75: 58.888889 | D75: 98.730159 | E75: 67.2
A76: 10 | B76: 22.05.2017 3 | C76: 13.555556 | D76: 99.120879 | E76: 97.066667
... A85: 1 | B85: 25.05.2017 3 | C85: 10.888889 | D85: 94.878049 | E85: 87.466667
